Workbook

Sheet 📖 Naming Convention
A1: SolidPro — Campaign Naming Convention Guide
A2: Follow this structure for every campaign, asset, and file name across both tracker files
A4: CAMPAIGN ID FORMAT
A5: VERTICAL-GOAL-DESCRIPTOR-MON-YY
A6: Examples: DT-LG-PLM-LAUNCH-APR25 IG-BD-VALVE-WHITEPAPER-JUN25 SE-TL-BRIDGE-CASESTUDY-Q3-25
A7: Note: Vertical Code + Goal Code + Short Descriptor (2–3 words max) + Month + 2-digit Year
A12: ASSET ID FORMAT (auto-generated in trackers)
A13: CAMPID-ASSETTYPE-SEQ
A14: Examples: DT-LG-PLM-LAUNCH-APR25-GD-001 (Graphic Design #1) DT-LG-PLM-LAUNCH-APR25-VD-001 (Video #1) DT-LG-PLM-LAUNCH-APR25-LP-001 (Landing Page #1)
A15: Note: Campaign ID + Asset Type Code + 3-digit sequence number
A20: VERTICAL CODES
A21: DT = Digital Transformation | IG = Industrial Goods | SE = Structural Engineering
... A46: Examples: 3. Descriptor must be 2–3 words max, no generic names like 'campaign1'. 4. Month is always 3-letter abbreviation: JAN FEB MAR APR MAY JUN JUL AUG SEP OCT NOV DEC 5. Year is always 2-digit: 25 for 2025.

Sheet 🗂 Campaign Master
A1: SolidPro — Campaign Master | FILE 1 of 2
A2: NAME FORMAT: VERTICAL-GOAL-DESCRIPTOR-MON-YY e.g. DT-LG-PLM-LAUNCH-APR25 | * = Mandatory | Creatives count is auto-calculated
A3: S.No | B3: Campaign ID * | C3: Campaign Name * | D3: Vertical * | E3: Goal Code | F3: Campaign Type | G3: Campaign Goal | H3: Target Audience | I3: Geography | J3: Campaign Start * | K3: Campaign End * | L3: Go-Live Date * | M3: Priority | N3: Campaign Owner * | O3: Campaign Status | P3: Approved by Project Head | Q3: Approved by Manager | R3: Creatives Count | S3: Notes / Brief
A4: 1 | B4: =IF(C4="","",IF(E4="",UPPER(SUBSTITUTE(LEFT(TRIM(C4),20)," ","-"))&"-"&TEXT(MONTH(TODAY()),"MMM")&RIGHT(YEAR(TODAY()),2),UPPER(E4)&"-"&UPPER(SUBSTITUTE(LEFT(TRIM(C4),15)," ","-"))&"-"&TEXT(MONTH(TODAY()),"MMM")&RIGHT(YEAR(TODAY()),2))) | R4: =COUNTIFS('🎨 Creatives'!$B$4:$B$103,B4,'🎨 Creatives'!$E$4:$E$103,"<>")
A5: 2 | B5: =IF(C5="","",IF(E5="",UPPER(SUBSTITUTE(LEFT(TRIM(C5),20)," ","-"))&"-"&TEXT(MONTH(TODAY()),"MMM")&RIGHT(YEAR(TODAY()),2),UPPER(E5)&"-"&UPPER(SUBSTITUTE(LEFT(TRIM(C5),15)," ","-"))&"-"&TEXT(MONTH(TODAY()),"MMM")&RIGHT(YEAR(TODAY()),2))) | R5: =COUNTIFS('🎨 Creatives'!$B$4:$B$103,B5,'🎨 Creatives'!$E$4:$E$103,"<>")
A6: 3 | B6: =IF(C6="","",IF(E6="",UPPER(SUBSTITUTE(LEFT(TRIM(C6),20)," ","-"))&"-"&TEXT(MONTH(TODAY()),"MMM")&RIGHT(YEAR(TODAY()),2),UPPER(E6)&"-"&UPPER(SUBSTITUTE(LEFT(TRIM(C6),15)," ","-"))&"-"&TEXT(MONTH(TODAY()),"MMM")&RIGHT(YEAR(TODAY()),2))) | R6: =COUNTIFS('🎨 Creatives'!$B$4:$B$103,B6,'🎨 Creatives'!$E$4:$E$103,"<>")
A7: 4 | B7: =IF(C7="","",IF(E7="",UPPER(SUBSTITUTE(LEFT(TRIM(C7),20)," ","-"))&"-"&TEXT(MONTH(TODAY()),"MMM")&RIGHT(YEAR(TODAY()),2),UPPER(E7)&"-"&UPPER(SUBSTITUTE(LEFT(TRIM(C7),15)," ","-"))&"-"&TEXT(MONTH(TODAY()),"MMM")&RIGHT(YEAR(TODAY()),2))) | R7: =COUNTIFS('🎨 Creatives'!$B$4:$B$103,B7,'🎨 Creatives'!$E$4:$E$103,"<>")
A8: 5 | B8: =IF(C8="","",IF(E8="",UPPER(SUBSTITUTE(LEFT(TRIM(C8),20)," ","-"))&"-"&TEXT(MONTH(TODAY()),"MMM")&RIGHT(YEAR(TODAY()),2),UPPER(E8)&"-"&UPPER(SUBSTITUTE(LEFT(TRIM(C8),15)," ","-"))&"-"&TEXT(MONTH(TODAY()),"MMM")&RIGHT(YEAR(TODAY()),2))) | R8: =COUNTIFS('🎨 Creatives'!$B$4:$B$103,B8,'🎨 Creatives'!$E$4:$E$103,"<>")
A9: 6 | B9: =IF(C9="","",IF(E9="",UPPER(SUBSTITUTE(LEFT(TRIM(C9),20)," ","-"))&"-"&TEXT(MONTH(TODAY()),"MMM")&RIGHT(YEAR(TODAY()),2),UPPER(E9)&"-"&UPPER(SUBSTITUTE(LEFT(TRIM(C9),15)," ","-"))&"-"&TEXT(MONTH(TODAY()),"MMM")&RIGHT(YEAR(TODAY()),2))) | R9: =COUNTIFS('🎨 Creatives'!$B$4:$B$103,B9,'🎨 Creatives'!$E$4:$E$103,"<>")
A10: 7 | B10: =IF(C10="","",IF(E10="",UPPER(SUBSTITUTE(LEFT(TRIM(C10),20)," ","-"))&"-"&TEXT(MONTH(TODAY()),"MMM")&RIGHT(YEAR(TODAY()),2),UPPER(E10)&"-"&UPPER(SUBSTITUTE(LEFT(TRIM(C10),15)," ","-"))&"-"&TEXT(MONTH(TODAY()),"MMM")&RIGHT(YEAR(TODAY()),2))) | R10: =COUNTIFS('🎨 Creatives'!$B$4:$B$103,B10,'🎨 Creatives'!$E$4:$E$103,"<>")
A11: 8 | B11: =IF(C11="","",IF(E11="",UPPER(SUBSTITUTE(LEFT(TRIM(C11),20)," ","-"))&"-"&TEXT(MONTH(TODAY()),"MMM")&RIGHT(YEAR(TODAY()),2),UPPER(E11)&"-"&UPPER(SUBSTITUTE(LEFT(TRIM(C11),15)," ","-"))&"-"&TEXT(MONTH(TODAY()),"MMM")&RIGHT(YEAR(TODAY()),2))) | R11: =COUNTIFS('🎨 Creatives'!$B$4:$B$103,B11,'🎨 Creatives'!$E$4:$E$103,"<>")
A12: 9 | B12: =IF(C12="","",IF(E12="",UPPER(SUBSTITUTE(LEFT(TRIM(C12),20)," ","-"))&"-"&TEXT(MONTH(TODAY()),"MMM")&RIGHT(YEAR(TODAY()),2),UPPER(E12)&"-"&UPPER(SUBSTITUTE(LEFT(TRIM(C12),15)," ","-"))&"-"&TEXT(MONTH(TODAY()),"MMM")&RIGHT(YEAR(TODAY()),2))) | R12: =COUNTIFS('🎨 Creatives'!$B$4:$B$103,B12,'🎨 Creatives'!$E$4:$E$103,"<>")
A13: 10 | B13: =IF(C13="","",IF(E13="",UPPER(SUBSTITUTE(LEFT(TRIM(C13),20)," ","-"))&"-"&TEXT(MONTH(TODAY()),"MMM")&RIGHT(YEAR(TODAY()),2),UPPER(E13)&"-"&UPPER(SUBSTITUTE(LEFT(TRIM(C13),15)," ","-"))&"-"&TEXT(MONTH(TODAY()),"MMM")&RIGHT(YEAR(TODAY()),2))) | R13: =COUNTIFS('🎨 Creatives'!$B$4:$B$103,B13,'🎨 Creatives'!$E$4:$E$103,"<>")
A14: 11 | B14: =IF(C14="","",IF(E14="",UPPER(SUBSTITUTE(LEFT(TRIM(C14),20)," ","-"))&"-"&TEXT(MONTH(TODAY()),"MMM")&RIGHT(YEAR(TODAY()),2),UPPER(E14)&"-"&UPPER(SUBSTITUTE(LEFT(TRIM(C14),15)," ","-"))&"-"&TEXT(MONTH(TODAY()),"MMM")&RIGHT(YEAR(TODAY()),2))) | R14: =COUNTIFS('🎨 Creatives'!$B$4:$B$103,B14,'🎨 Creatives'!$E$4:$E$103,"<>")
A15: 12 | B15: =IF(C15="","",IF(E15="",UPPER(SUBSTITUTE(LEFT(TRIM(C15),20)," ","-"))&"-"&TEXT(MONTH(TODAY()),"MMM")&RIGHT(YEAR(TODAY()),2),UPPER(E15)&"-"&UPPER(SUBSTITUTE(LEFT(TRIM(C15),15)," ","-"))&"-"&TEXT(MONTH(TODAY()),"MMM")&RIGHT(YEAR(TODAY()),2))) | R15: =COUNTIFS('🎨 Creatives'!$B$4:$B$103,B15,'🎨 Creatives'!$E$4:$E$103,"<>")
... A103: 100 | B103: =IF(C103="","",IF(E103="",UPPER(SUBSTITUTE(LEFT(TRIM(C103),20)," ","-"))&"-"&TEXT(MONTH(TODAY()),"MMM")&RIGHT(YEAR(TODAY()),2),UPPER(E103)&"-"&UPPER(SUBSTITUTE(LEFT(TRIM(C103),15)," ","-"))&"-"&TEXT(MONTH(TODAY()),"MMM")&RIGHT(YEAR(TODAY()),2))) | R103: =COUNTIFS('🎨 Creatives'!$B$4:$B$103,B103,'🎨 Creatives'!$E$4:$E$103,"<>")

Sheet 🎨 Creatives
A1: SolidPro — Creatives Tracker (Graphic Design & Video) | FILE 1 of 2
A2: Asset ID auto-generated from Campaign ID | Asset naming: CAMPID-GD-001 / CAMPID-VD-001 | * = Mandatory
A3: S.No | B3: Campaign ID * | C3: Asset ID | D3: Vertical * | E3: Asset Name / Title * | F3: Content Type | G3: Asset Type | H3: Format / Size | I3: Platform | J3: Brief / Description | K3: Owner (Designer/Video) * | L3: Support (Copywriter) | M3: Requested By | N3: Brief Date | O3: Due Date * | P3: Post Date * | Q3: Priority | R3: Status | S3: Approved by Project Head | T3: Approved by Manager | U3: Final File Link | V3: Revision # | W3: Feedback / Notes | X3: Archived?
A4: 1 | C4: =IF(B4="","",IF(G4="",B4&"-AST-"&TEXT(1,"000"),B4&"-"&IF(G4="Graphic Design","GD",IF(G4="Video","VD",IF(G4="Motion Graphic","MG","AST")))&"-"&TEXT(1,"000")))
A5: 2 | C5: =IF(B5="","",IF(G5="",B5&"-AST-"&TEXT(2,"000"),B5&"-"&IF(G5="Graphic Design","GD",IF(G5="Video","VD",IF(G5="Motion Graphic","MG","AST")))&"-"&TEXT(2,"000")))
A6: 3 | C6: =IF(B6="","",IF(G6="",B6&"-AST-"&TEXT(3,"000"),B6&"-"&IF(G6="Graphic Design","GD",IF(G6="Video","VD",IF(G6="Motion Graphic","MG","AST")))&"-"&TEXT(3,"000")))
A7: 4 | C7: =IF(B7="","",IF(G7="",B7&"-AST-"&TEXT(4,"000"),B7&"-"&IF(G7="Graphic Design","GD",IF(G7="Video","VD",IF(G7="Motion Graphic","MG","AST")))&"-"&TEXT(4,"000")))
A8: 5 | C8: =IF(B8="","",IF(G8="",B8&"-AST-"&TEXT(5,"000"),B8&"-"&IF(G8="Graphic Design","GD",IF(G8="Video","VD",IF(G8="Motion Graphic","MG","AST")))&"-"&TEXT(5,"000")))
A9: 6 | C9: =IF(B9="","",IF(G9="",B9&"-AST-"&TEXT(6,"000"),B9&"-"&IF(G9="Graphic Design","GD",IF(G9="Video","VD",IF(G9="Motion Graphic","MG","AST")))&"-"&TEXT(6,"000")))
A10: 7 | C10: =IF(B10="","",IF(G10="",B10&"-AST-"&TEXT(7,"000"),B10&"-"&IF(G10="Graphic Design","GD",IF(G10="Video","VD",IF(G10="Motion Graphic","MG","AST")))&"-"&TEXT(7,"000")))
A11: 8 | C11: =IF(B11="","",IF(G11="",B11&"-AST-"&TEXT(8,"000"),B11&"-"&IF(G11="Graphic Design","GD",IF(G11="Video","VD",IF(G11="Motion Graphic","MG","AST")))&"-"&TEXT(8,"000")))
A12: 9 | C12: =IF(B12="","",IF(G12="",B12&"-AST-"&TEXT(9,"000"),B12&"-"&IF(G12="Graphic Design","GD",IF(G12="Video","VD",IF(G12="Motion Graphic","MG","AST")))&"-"&TEXT(9,"000")))
A13: 10 | C13: =IF(B13="","",IF(G13="",B13&"-AST-"&TEXT(10,"000"),B13&"-"&IF(G13="Graphic Design","GD",IF(G13="Video","VD",IF(G13="Motion Graphic","MG","AST")))&"-"&TEXT(10,"000")))
A14: 11 | C14: =IF(B14="","",IF(G14="",B14&"-AST-"&TEXT(11,"000"),B14&"-"&IF(G14="Graphic Design","GD",IF(G14="Video","VD",IF(G14="Motion Graphic","MG","AST")))&"-"&TEXT(11,"000")))
A15: 12 | C15: =IF(B15="","",IF(G15="",B15&"-AST-"&TEXT(12,"000"),B15&"-"&IF(G15="Graphic Design","GD",IF(G15="Video","VD",IF(G15="Motion Graphic","MG","AST")))&"-"&TEXT(12,"000")))
A16: 13 | C16: =IF(B16="","",IF(G16="",B16&"-AST-"&TEXT(13,"000"),B16&"-"&IF(G16="Graphic Design","GD",IF(G16="Video","VD",IF(G16="Motion Graphic","MG","AST")))&"-"&TEXT(13,"000")))
A17: 14 | C17: =IF(B17="","",IF(G17="",B17&"-AST-"&TEXT(14,"000"),B17&"-"&IF(G17="Graphic Design","GD",IF(G17="Video","VD",IF(G17="Motion Graphic","MG","AST")))&"-"&TEXT(14,"000")))
A18: 15 | C18: =IF(B18="","",IF(G18="",B18&"-AST-"&TEXT(15,"000"),B18&"-"&IF(G18="Graphic Design","GD",IF(G18="Video","VD",IF(G18="Motion Graphic","MG","AST")))&"-"&TEXT(15,"000")))
A19: 16 | C19: =IF(B19="","",IF(G19="",B19&"-AST-"&TEXT(16,"000"),B19&"-"&IF(G19="Graphic Design","GD",IF(G19="Video","VD",IF(G19="Motion Graphic","MG","AST")))&"-"&TEXT(16,"000")))
A20: 17 | C20: =IF(B20="","",IF(G20="",B20&"-AST-"&TEXT(17,"000"),B20&"-"&IF(G20="Graphic Design","GD",IF(G20="Video","VD",IF(G20="Motion Graphic","MG","AST")))&"-"&TEXT(17,"000")))
A21: 18 | C21: =IF(B21="","",IF(G21="",B21&"-AST-"&TEXT(18,"000"),B21&"-"&IF(G21="Graphic Design","GD",IF(G21="Video","VD",IF(G21="Motion Graphic","MG","AST")))&"-"&TEXT(18,"000")))
A22: 19 | C22: =IF(B22="","",IF(G22="",B22&"-AST-"&TEXT(19,"000"),B22&"-"&IF(G22="Graphic Design","GD",IF(G22="Video","VD",IF(G22="Motion Graphic","MG","AST")))&"-"&TEXT(19,"000")))
A23: 20 | C23: =IF(B23="","",IF(G23="",B23&"-AST-"&TEXT(20,"000"),B23&"-"&IF(G23="Graphic Design","GD",IF(G23="Video","VD",IF(G23="Motion Graphic","MG","AST")))&"-"&TEXT(20,"000")))
A24: 21 | C24: =IF(B24="","",IF(G24="",B24&"-AST-"&TEXT(21,"000"),B24&"-"&IF(G24="Graphic Design","GD",IF(G24="Video","VD",IF(G24="Motion Graphic","MG","AST")))&"-"&TEXT(21,"000")))
A25: 22 | C25: =IF(B25="","",IF(G25="",B25&"-AST-"&TEXT(22,"000"),B25&"-"&IF(G25="Graphic Design","GD",IF(G25="Video","VD",IF(G25="Motion Graphic","MG","AST")))&"-"&TEXT(22,"000")))
A26: 23 | C26: =IF(B26="","",IF(G26="",B26&"-AST-"&TEXT(23,"000"),B26&"-"&IF(G26="Graphic Design","GD",IF(G26="Video","VD",IF(G26="Motion Graphic","MG","AST")))&"-"&TEXT(23,"000")))
A27: 24 | C27: =IF(B27="","",IF(G27="",B27&"-AST-"&TEXT(24,"000"),B27&"-"&IF(G27="Graphic Design","GD",IF(G27="Video","VD",IF(G27="Motion Graphic","MG","AST")))&"-"&TEXT(24,"000")))
A28: 25 | C28: =IF(B28="","",IF(G28="",B28&"-AST-"&TEXT(25,"000"),B28&"-"&IF(G28="Graphic Design","GD",IF(G28="Video","VD",IF(G28="Motion Graphic","MG","AST")))&"-"&TEXT(25,"000")))
A29: 26 | C29: =IF(B29="","",IF(G29="",B29&"-AST-"&TEXT(26,"000"),B29&"-"&IF(G29="Graphic Design","GD",IF(G29="Video","VD",IF(G29="Motion Graphic","MG","AST")))&"-"&TEXT(26,"000")))
A30: 27 | C30: =IF(B30="","",IF(G30="",B30&"-AST-"&TEXT(27,"000"),B30&"-"&IF(G30="Graphic Design","GD",IF(G30="Video","VD",IF(G30="Motion Graphic","MG","AST")))&"-"&TEXT(27,"000")))
A31: 28 | C31: =IF(B31="","",IF(G31="",B31&"-AST-"&TEXT(28,"000"),B31&"-"&IF(G31="Graphic Design","GD",IF(G31="Video","VD",IF(G31="Motion Graphic","MG","AST")))&"-"&TEXT(28,"000")))
A32: 29 | C32: =IF(B32="","",IF(G32="",B32&"-AST-"&TEXT(29,"000"),B32&"-"&IF(G32="Graphic Design","GD",IF(G32="Video","VD",IF(G32="Motion Graphic","MG","AST")))&"-"&TEXT(29,"000")))
A33: 30 | C33: =IF(B33="","",IF(G33="",B33&"-AST-"&TEXT(30,"000"),B33&"-"&IF(G33="Graphic Design","GD",IF(G33="Video","VD",IF(G33="Motion Graphic","MG","AST")))&"-"&TEXT(30,"000")))
A34: 31 | C34: =IF(B34="","",IF(G34="",B34&"-AST-"&TEXT(31,"000"),B34&"-"&IF(G34="Graphic Design","GD",IF(G34="Video","VD",IF(G34="Motion Graphic","MG","AST")))&"-"&TEXT(31,"000")))
A35: 32 | C35: =IF(B35="","",IF(G35="",B35&"-AST-"&TEXT(32,"000"),B35&"-"&IF(G35="Graphic Design","GD",IF(G35="Video","VD",IF(G35="Motion Graphic","MG","AST")))&"-"&TEXT(32,"000")))
A36: 33 | C36: =IF(B36="","",IF(G36="",B36&"-AST-"&TEXT(33,"000"),B36&"-"&IF(G36="Graphic Design","GD",IF(G36="Video","VD",IF(G36="Motion Graphic","MG","AST")))&"-"&TEXT(33,"000")))
A37: 34 | C37: =IF(B37="","",IF(G37="",B37&"-AST-"&TEXT(34,"000"),B37&"-"&IF(G37="Graphic Design","GD",IF(G37="Video","VD",IF(G37="Motion Graphic","MG","AST")))&"-"&TEXT(34,"000")))
A38: 35 | C38: =IF(B38="","",IF(G38="",B38&"-AST-"&TEXT(35,"000"),B38&"-"&IF(G38="Graphic Design","GD",IF(G38="Video","VD",IF(G38="Motion Graphic","MG","AST")))&"-"&TEXT(35,"000")))
A39: 36 | C39: =IF(B39="","",IF(G39="",B39&"-AST-"&TEXT(36,"000"),B39&"-"&IF(G39="Graphic Design","GD",IF(G39="Video","VD",IF(G39="Motion Graphic","MG","AST")))&"-"&TEXT(36,"000")))
A40: 37 | C40: =IF(B40="","",IF(G40="",B40&"-AST-"&TEXT(37,"000"),B40&"-"&IF(G40="Graphic Design","GD",IF(G40="Video","VD",IF(G40="Motion Graphic","MG","AST")))&"-"&TEXT(37,"000")))
...

Sheet 📣 Ad Copy
A1: SolidPro — Ad Copy Tracker | FILE 1 of 2
A2: Asset ID format: CAMPID-AD-001 | Link Destination URL and Creative ID before publishing | * = Mandatory
A3: S.No | B3: Campaign ID * | C3: Asset ID | D3: Vertical * | E3: Ad Name / Title * | F3: Ad Platform | G3: Ad Format | H3: Ad Objective | I3: Headline 1 | J3: Headline 2 | K3: Body Copy | L3: CTA Text | M3: Destination URL | N3: Linked Creative ID | O3: Audience Targeting | P3: Budget (INR) | Q3: Run Start Date | R3: Run End Date | S3: UTM Parameters | T3: Owner * | U3: Due Date * | V3: Priority | W3: Status | X3: Approved by Project Head | Y3: Approved by Manager | Z3: Notes
A4: 1 | C4: =IF(B4="","",B4&"-AD-"&TEXT(1,"000"))
A5: 2 | C5: =IF(B5="","",B5&"-AD-"&TEXT(2,"000"))
A6: 3 | C6: =IF(B6="","",B6&"-AD-"&TEXT(3,"000"))
A7: 4 | C7: =IF(B7="","",B7&"-AD-"&TEXT(4,"000"))
A8: 5 | C8: =IF(B8="","",B8&"-AD-"&TEXT(5,"000"))
A9: 6 | C9: =IF(B9="","",B9&"-AD-"&TEXT(6,"000"))
A10: 7 | C10: =IF(B10="","",B10&"-AD-"&TEXT(7,"000"))
A11: 8 | C11: =IF(B11="","",B11&"-AD-"&TEXT(8,"000"))
A12: 9 | C12: =IF(B12="","",B12&"-AD-"&TEXT(9,"000"))
A13: 10 | C13: =IF(B13="","",B13&"-AD-"&TEXT(10,"000"))
A14: 11 | C14: =IF(B14="","",B14&"-AD-"&TEXT(11,"000"))
A15: 12 | C15: =IF(B15="","",B15&"-AD-"&TEXT(12,"000"))
A16: 13 | C16: =IF(B16="","",B16&"-AD-"&TEXT(13,"000"))
A17: 14 | C17: =IF(B17="","",B17&"-AD-"&TEXT(14,"000"))
A18: 15 | C18: =IF(B18="","",B18&"-AD-"&TEXT(15,"000"))
A19: 16 | C19: =IF(B19="","",B19&"-AD-"&TEXT(16,"000"))
A20: 17 | C20: =IF(B20="","",B20&"-AD-"&TEXT(17,"000"))
A21: 18 | C21: =IF(B21="","",B21&"-AD-"&TEXT(18,"000"))
A22: 19 | C22: =IF(B22="","",B22&"-AD-"&TEXT(19,"000"))
A23: 20 | C23: =IF(B23="","",B23&"-AD-"&TEXT(20,"000"))
A24: 21 | C24: =IF(B24="","",B24&"-AD-"&TEXT(21,"000"))
A25: 22 | C25: =IF(B25="","",B25&"-AD-"&TEXT(22,"000"))
A26: 23 | C26: =IF(B26="","",B26&"-AD-"&TEXT(23,"000"))
A27: 24 | C27: =IF(B27="","",B27&"-AD-"&TEXT(24,"000"))
A28: 25 | C28: =IF(B28="","",B28&"-AD-"&TEXT(25,"000"))
A29: 26 | C29: =IF(B29="","",B29&"-AD-"&TEXT(26,"000"))
A30: 27 | C30: =IF(B30="","",B30&"-AD-"&TEXT(27,"000"))
A31: 28 | C31: =IF(B31="","",B31&"-AD-"&TEXT(28,"000"))
A32: 29 | C32: =IF(B32="","",B32&"-AD-"&TEXT(29,"000"))
A33: 30 | C33: =IF(B33="","",B33&"-AD-"&TEXT(30,"000"))
A34: 31 | C34: =IF(B34="","",B34&"-AD-"&TEXT(31,"000"))
A35: 32 | C35: =IF(B35="","",B35&"-AD-"&TEXT(32,"000"))
A36: 33 | C36: =IF(B36="","",B36&"-AD-"&TEXT(33,"000"))
A37: 34 | C37: =IF(B37="","",B37&"-AD-"&TEXT(34,"000"))
A38: 35 | C38: =IF(B38="","",B38&"-AD-"&TEXT(35,"000"))
A39: 36 | C39: =IF(B39="","",B39&"-AD-"&TEXT(36,"000"))
A40: 37 | C40: =IF(B40="","",B40&"-AD-"&TEXT(37,"000"))
...

Sheet 📊 Dashboard
A1: SolidPro — Campaign + Creatives Dashboard (File 1 of 2)
A2: Auto-calculated | Press Ctrl+Alt+F9 to force refresh all formulas
A4: Campaigns by Status | D4: Count
A5: 🗓 Planning | D5: =COUNTIF('🗂 Campaign Master'!O4:O103,"*Planning*")
A6: 🚀 Active | D6: =COUNTIF('🗂 Campaign Master'!O4:O103,"*Active*")
A7: ✅ Completed | D7: =COUNTIF('🗂 Campaign Master'!O4:O103,"*Completed*")
A8: ⏸ Paused | D8: =COUNTIF('🗂 Campaign Master'!O4:O103,"*Paused*")
A9: ❌ Cancelled | D9: =COUNTIF('🗂 Campaign Master'!O4:O103,"*Cancelled*")
A12: Creatives by Status | D12: Count
A13: 📋 Briefed | D13: =COUNTIF('🎨 Creatives'!R4:R103,"*Briefed*")
A14: ✍ In Progress | D14: =COUNTIF('🎨 Creatives'!R4:R103,"*Progress*")
A15: 🔁 In Revision | D15: =COUNTIF('🎨 Creatives'!R4:R103,"*Revision*")
A16: ✅ Approved – PH | D16: =COUNTIF('🎨 Creatives'!R4:R103,"*Approved by Project Head*")
A17: ✅ Approved – Manager | D17: =COUNTIF('🎨 Creatives'!R4:R103,"*Approved by Manager*")
A18: 🚀 Published | D18: =COUNTIF('🎨 Creatives'!R4:R103,"*Published*")
A19: ⏸ On Hold | D19: =COUNTIF('🎨 Creatives'!R4:R103,"*On Hold*")
A20: ❌ Cancelled | D20: =COUNTIF('🎨 Creatives'!R4:R103,"*Cancelled*")
A23: Campaigns by Vertical | D23: Count
A24: Digital Transformation | D24: =COUNTIF('🗂 Campaign Master'!D4:D103,"*Digital Transformation*")
A25: Industrial Goods & Consumer Products | D25: =COUNTIF('🗂 Campaign Master'!D4:D103,"*Industrial Goods & Consumer Products*")
A26: Structural Engineering | D26: =COUNTIF('🗂 Campaign Master'!D4:D103,"*Structural Engineering*")
A27: MedTech | D27: =COUNTIF('🗂 Campaign Master'!D4:D103,"*MedTech*")
A28: Energy & Utilities | D28: =COUNTIF('🗂 Campaign Master'!D4:D103,"*Energy & Utilities*")
A29: Sustainability | D29: =COUNTIF('🗂 Campaign Master'!D4:D103,"*Sustainability*")
A30: BFSI | D30: =COUNTIF('🗂 Campaign Master'!D4:D103,"*BFSI*")
A31: Product Innovation | D31: =COUNTIF('🗂 Campaign Master'!D4:D103,"*Product Innovation*")
A32: SolidPro AI | D32: =COUNTIF('🗂 Campaign Master'!D4:D103,"*SolidPro AI*")
A33: Other | D33: =COUNTIF('🗂 Campaign Master'!D4:D103,"*Other*")
