Workbook

Sheet 🗂 Campaign Master
A1: SolidPro Engineering — Campaign Master
A2: Every asset in all tabs must reference a Campaign ID from this sheet | * = Mandatory
A3: S.No | B3: Campaign ID * | C3: Campaign Name * | D3: Vertical * | E3: Campaign Goal | F3: Target Audience | G3: Geography | H3: Campaign Type | I3: Campaign Start * | J3: Campaign End * | K3: Go-Live Date * | L3: Priority | M3: Campaign Owner | N3: Campaign Status | O3: Approved by Project Head | P3: Approved by Manager | Q3: Total Assets | R3: Notes / Brief
A4: 1 | B4: =IF(C4="","","CAMP-"&TEXT(1,"000")) | Q4: =COUNTIFS('🎨 Creatives'!$B$4:$B$53,B4,'🎨 Creatives'!$E$4:$E$53,"<>")+COUNTIFS('🌐 Landing Pages'!$B$4:$B$53,B4,'🌐 Landing Pages'!$E$4:$E$53,"<>")+COUNTIFS('✍ Content Writing'!$B$4:$B$53,B4,'✍ Content Writing'!$E$4:$E$53,"<>")+COUNTIFS('🎁 Lead Magnets'!$B$4:$B$53,B4,'🎁 Lead Magnets'!$E$4:$E$53,"<>")+COUNTIFS('📧 Email Sequences'!$B$4:$B$53,B4,'📧 Email Sequences'!$E$4:$E$53,"<>")+COUNTIFS('📣 Ad Copy'!$B$4:$B$53,B4,'📣 Ad Copy'!$E$4:$E$53,"<>")+COUNTIFS('🔍 SEO'!$B$4:$B$53,B4,'🔍 SEO'!$E$4:$E$53,"<>")+COUNTIFS('🎤 Webinars & Events'!$B$4:$B$53,B4,'🎤 Webinars & Events'!$E$4:$E$53,"<>")
A5: 2 | B5: =IF(C5="","","CAMP-"&TEXT(2,"000")) | Q5: =COUNTIFS('🎨 Creatives'!$B$4:$B$53,B5,'🎨 Creatives'!$E$4:$E$53,"<>")+COUNTIFS('🌐 Landing Pages'!$B$4:$B$53,B5,'🌐 Landing Pages'!$E$4:$E$53,"<>")+COUNTIFS('✍ Content Writing'!$B$4:$B$53,B5,'✍ Content Writing'!$E$4:$E$53,"<>")+COUNTIFS('🎁 Lead Magnets'!$B$4:$B$53,B5,'🎁 Lead Magnets'!$E$4:$E$53,"<>")+COUNTIFS('📧 Email Sequences'!$B$4:$B$53,B5,'📧 Email Sequences'!$E$4:$E$53,"<>")+COUNTIFS('📣 Ad Copy'!$B$4:$B$53,B5,'📣 Ad Copy'!$E$4:$E$53,"<>")+COUNTIFS('🔍 SEO'!$B$4:$B$53,B5,'🔍 SEO'!$E$4:$E$53,"<>")+COUNTIFS('🎤 Webinars & Events'!$B$4:$B$53,B5,'🎤 Webinars & Events'!$E$4:$E$53,"<>")
A6: 3 | B6: =IF(C6="","","CAMP-"&TEXT(3,"000")) | Q6: =COUNTIFS('🎨 Creatives'!$B$4:$B$53,B6,'🎨 Creatives'!$E$4:$E$53,"<>")+COUNTIFS('🌐 Landing Pages'!$B$4:$B$53,B6,'🌐 Landing Pages'!$E$4:$E$53,"<>")+COUNTIFS('✍ Content Writing'!$B$4:$B$53,B6,'✍ Content Writing'!$E$4:$E$53,"<>")+COUNTIFS('🎁 Lead Magnets'!$B$4:$B$53,B6,'🎁 Lead Magnets'!$E$4:$E$53,"<>")+COUNTIFS('📧 Email Sequences'!$B$4:$B$53,B6,'📧 Email Sequences'!$E$4:$E$53,"<>")+COUNTIFS('📣 Ad Copy'!$B$4:$B$53,B6,'📣 Ad Copy'!$E$4:$E$53,"<>")+COUNTIFS('🔍 SEO'!$B$4:$B$53,B6,'🔍 SEO'!$E$4:$E$53,"<>")+COUNTIFS('🎤 Webinars & Events'!$B$4:$B$53,B6,'🎤 Webinars & Events'!$E$4:$E$53,"<>")
A7: 4 | B7: =IF(C7="","","CAMP-"&TEXT(4,"000")) | Q7: =COUNTIFS('🎨 Creatives'!$B$4:$B$53,B7,'🎨 Creatives'!$E$4:$E$53,"<>")+COUNTIFS('🌐 Landing Pages'!$B$4:$B$53,B7,'🌐 Landing Pages'!$E$4:$E$53,"<>")+COUNTIFS('✍ Content Writing'!$B$4:$B$53,B7,'✍ Content Writing'!$E$4:$E$53,"<>")+COUNTIFS('🎁 Lead Magnets'!$B$4:$B$53,B7,'🎁 Lead Magnets'!$E$4:$E$53,"<>")+COUNTIFS('📧 Email Sequences'!$B$4:$B$53,B7,'📧 Email Sequences'!$E$4:$E$53,"<>")+COUNTIFS('📣 Ad Copy'!$B$4:$B$53,B7,'📣 Ad Copy'!$E$4:$E$53,"<>")+COUNTIFS('🔍 SEO'!$B$4:$B$53,B7,'🔍 SEO'!$E$4:$E$53,"<>")+COUNTIFS('🎤 Webinars & Events'!$B$4:$B$53,B7,'🎤 Webinars & Events'!$E$4:$E$53,"<>")
A8: 5 | B8: =IF(C8="","","CAMP-"&TEXT(5,"000")) | Q8: =COUNTIFS('🎨 Creatives'!$B$4:$B$53,B8,'🎨 Creatives'!$E$4:$E$53,"<>")+COUNTIFS('🌐 Landing Pages'!$B$4:$B$53,B8,'🌐 Landing Pages'!$E$4:$E$53,"<>")+COUNTIFS('✍ Content Writing'!$B$4:$B$53,B8,'✍ Content Writing'!$E$4:$E$53,"<>")+COUNTIFS('🎁 Lead Magnets'!$B$4:$B$53,B8,'🎁 Lead Magnets'!$E$4:$E$53,"<>")+COUNTIFS('📧 Email Sequences'!$B$4:$B$53,B8,'📧 Email Sequences'!$E$4:$E$53,"<>")+COUNTIFS('📣 Ad Copy'!$B$4:$B$53,B8,'📣 Ad Copy'!$E$4:$E$53,"<>")+COUNTIFS('🔍 SEO'!$B$4:$B$53,B8,'🔍 SEO'!$E$4:$E$53,"<>")+COUNTIFS('🎤 Webinars & Events'!$B$4:$B$53,B8,'🎤 Webinars & Events'!$E$4:$E$53,"<>")
A9: 6 | B9: =IF(C9="","","CAMP-"&TEXT(6,"000")) | Q9: =COUNTIFS('🎨 Creatives'!$B$4:$B$53,B9,'🎨 Creatives'!$E$4:$E$53,"<>")+COUNTIFS('🌐 Landing Pages'!$B$4:$B$53,B9,'🌐 Landing Pages'!$E$4:$E$53,"<>")+COUNTIFS('✍ Content Writing'!$B$4:$B$53,B9,'✍ Content Writing'!$E$4:$E$53,"<>")+COUNTIFS('🎁 Lead Magnets'!$B$4:$B$53,B9,'🎁 Lead Magnets'!$E$4:$E$53,"<>")+COUNTIFS('📧 Email Sequences'!$B$4:$B$53,B9,'📧 Email Sequences'!$E$4:$E$53,"<>")+COUNTIFS('📣 Ad Copy'!$B$4:$B$53,B9,'📣 Ad Copy'!$E$4:$E$53,"<>")+COUNTIFS('🔍 SEO'!$B$4:$B$53,B9,'🔍 SEO'!$E$4:$E$53,"<>")+COUNTIFS('🎤 Webinars & Events'!$B$4:$B$53,B9,'🎤 Webinars & Events'!$E$4:$E$53,"<>")
A10: 7 | B10: =IF(C10="","","CAMP-"&TEXT(7,"000")) | Q10: =COUNTIFS('🎨 Creatives'!$B$4:$B$53,B10,'🎨 Creatives'!$E$4:$E$53,"<>")+COUNTIFS('🌐 Landing Pages'!$B$4:$B$53,B10,'🌐 Landing Pages'!$E$4:$E$53,"<>")+COUNTIFS('✍ Content Writing'!$B$4:$B$53,B10,'✍ Content Writing'!$E$4:$E$53,"<>")+COUNTIFS('🎁 Lead Magnets'!$B$4:$B$53,B10,'🎁 Lead Magnets'!$E$4:$E$53,"<>")+COUNTIFS('📧 Email Sequences'!$B$4:$B$53,B10,'📧 Email Sequences'!$E$4:$E$53,"<>")+COUNTIFS('📣 Ad Copy'!$B$4:$B$53,B10,'📣 Ad Copy'!$E$4:$E$53,"<>")+COUNTIFS('🔍 SEO'!$B$4:$B$53,B10,'🔍 SEO'!$E$4:$E$53,"<>")+COUNTIFS('🎤 Webinars & Events'!$B$4:$B$53,B10,'🎤 Webinars & Events'!$E$4:$E$53,"<>")
A11: 8 | B11: =IF(C11="","","CAMP-"&TEXT(8,"000")) | Q11: =COUNTIFS('🎨 Creatives'!$B$4:$B$53,B11,'🎨 Creatives'!$E$4:$E$53,"<>")+COUNTIFS('🌐 Landing Pages'!$B$4:$B$53,B11,'🌐 Landing Pages'!$E$4:$E$53,"<>")+COUNTIFS('✍ Content Writing'!$B$4:$B$53,B11,'✍ Content Writing'!$E$4:$E$53,"<>")+COUNTIFS('🎁 Lead Magnets'!$B$4:$B$53,B11,'🎁 Lead Magnets'!$E$4:$E$53,"<>")+COUNTIFS('📧 Email Sequences'!$B$4:$B$53,B11,'📧 Email Sequences'!$E$4:$E$53,"<>")+COUNTIFS('📣 Ad Copy'!$B$4:$B$53,B11,'📣 Ad Copy'!$E$4:$E$53,"<>")+COUNTIFS('🔍 SEO'!$B$4:$B$53,B11,'🔍 SEO'!$E$4:$E$53,"<>")+COUNTIFS('🎤 Webinars & Events'!$B$4:$B$53,B11,'🎤 Webinars & Events'!$E$4:$E$53,"<>")
A12: 9 | B12: =IF(C12="","","CAMP-"&TEXT(9,"000")) | Q12: =COUNTIFS('🎨 Creatives'!$B$4:$B$53,B12,'🎨 Creatives'!$E$4:$E$53,"<>")+COUNTIFS('🌐 Landing Pages'!$B$4:$B$53,B12,'🌐 Landing Pages'!$E$4:$E$53,"<>")+COUNTIFS('✍ Content Writing'!$B$4:$B$53,B12,'✍ Content Writing'!$E$4:$E$53,"<>")+COUNTIFS('🎁 Lead Magnets'!$B$4:$B$53,B12,'🎁 Lead Magnets'!$E$4:$E$53,"<>")+COUNTIFS('📧 Email Sequences'!$B$4:$B$53,B12,'📧 Email Sequences'!$E$4:$E$53,"<>")+COUNTIFS('📣 Ad Copy'!$B$4:$B$53,B12,'📣 Ad Copy'!$E$4:$E$53,"<>")+COUNTIFS('🔍 SEO'!$B$4:$B$53,B12,'🔍 SEO'!$E$4:$E$53,"<>")+COUNTIFS('🎤 Webinars & Events'!$B$4:$B$53,B12,'🎤 Webinars & Events'!$E$4:$E$53,"<>")
A13: 10 | B13: =IF(C13="","","CAMP-"&TEXT(10,"000")) | Q13: =COUNTIFS('🎨 Creatives'!$B$4:$B$53,B13,'🎨 Creatives'!$E$4:$E$53,"<>")+COUNTIFS('🌐 Landing Pages'!$B$4:$B$53,B13,'🌐 Landing Pages'!$E$4:$E$53,"<>")+COUNTIFS('✍ Content Writing'!$B$4:$B$53,B13,'✍ Content Writing'!$E$4:$E$53,"<>")+COUNTIFS('🎁 Lead Magnets'!$B$4:$B$53,B13,'🎁 Lead Magnets'!$E$4:$E$53,"<>")+COUNTIFS('📧 Email Sequences'!$B$4:$B$53,B13,'📧 Email Sequences'!$E$4:$E$53,"<>")+COUNTIFS('📣 Ad Copy'!$B$4:$B$53,B13,'📣 Ad Copy'!$E$4:$E$53,"<>")+COUNTIFS('🔍 SEO'!$B$4:$B$53,B13,'🔍 SEO'!$E$4:$E$53,"<>")+COUNTIFS('🎤 Webinars & Events'!$B$4:$B$53,B13,'🎤 Webinars & Events'!$E$4:$E$53,"<>")
A14: 11 | B14: =IF(C14="","","CAMP-"&TEXT(11,"000")) | Q14: =COUNTIFS('🎨 Creatives'!$B$4:$B$53,B14,'🎨 Creatives'!$E$4:$E$53,"<>")+COUNTIFS('🌐 Landing Pages'!$B$4:$B$53,B14,'🌐 Landing Pages'!$E$4:$E$53,"<>")+COUNTIFS('✍ Content Writing'!$B$4:$B$53,B14,'✍ Content Writing'!$E$4:$E$53,"<>")+COUNTIFS('🎁 Lead Magnets'!$B$4:$B$53,B14,'🎁 Lead Magnets'!$E$4:$E$53,"<>")+COUNTIFS('📧 Email Sequences'!$B$4:$B$53,B14,'📧 Email Sequences'!$E$4:$E$53,"<>")+COUNTIFS('📣 Ad Copy'!$B$4:$B$53,B14,'📣 Ad Copy'!$E$4:$E$53,"<>")+COUNTIFS('🔍 SEO'!$B$4:$B$53,B14,'🔍 SEO'!$E$4:$E$53,"<>")+COUNTIFS('🎤 Webinars & Events'!$B$4:$B$53,B14,'🎤 Webinars & Events'!$E$4:$E$53,"<>")
A15: 12 | B15: =IF(C15="","","CAMP-"&TEXT(12,"000")) | Q15: =COUNTIFS('🎨 Creatives'!$B$4:$B$53,B15,'🎨 Creatives'!$E$4:$E$53,"<>")+COUNTIFS('🌐 Landing Pages'!$B$4:$B$53,B15,'🌐 Landing Pages'!$E$4:$E$53,"<>")+COUNTIFS('✍ Content Writing'!$B$4:$B$53,B15,'✍ Content Writing'!$E$4:$E$53,"<>")+COUNTIFS('🎁 Lead Magnets'!$B$4:$B$53,B15,'🎁 Lead Magnets'!$E$4:$E$53,"<>")+COUNTIFS('📧 Email Sequences'!$B$4:$B$53,B15,'📧 Email Sequences'!$E$4:$E$53,"<>")+COUNTIFS('📣 Ad Copy'!$B$4:$B$53,B15,'📣 Ad Copy'!$E$4:$E$53,"<>")+COUNTIFS('🔍 SEO'!$B$4:$B$53,B15,'🔍 SEO'!$E$4:$E$53,"<>")+COUNTIFS('🎤 Webinars & Events'!$B$4:$B$53,B15,'🎤 Webinars & Events'!$E$4:$E$53,"<>")
A16: 13 | B16: =IF(C16="","","CAMP-"&TEXT(13,"000")) | Q16: =COUNTIFS('🎨 Creatives'!$B$4:$B$53,B16,'🎨 Creatives'!$E$4:$E$53,"<>")+COUNTIFS('🌐 Landing Pages'!$B$4:$B$53,B16,'🌐 Landing Pages'!$E$4:$E$53,"<>")+COUNTIFS('✍ Content Writing'!$B$4:$B$53,B16,'✍ Content Writing'!$E$4:$E$53,"<>")+COUNTIFS('🎁 Lead Magnets'!$B$4:$B$53,B16,'🎁 Lead Magnets'!$E$4:$E$53,"<>")+COUNTIFS('📧 Email Sequences'!$B$4:$B$53,B16,'📧 Email Sequences'!$E$4:$E$53,"<>")+COUNTIFS('📣 Ad Copy'!$B$4:$B$53,B16,'📣 Ad Copy'!$E$4:$E$53,"<>")+COUNTIFS('🔍 SEO'!$B$4:$B$53,B16,'🔍 SEO'!$E$4:$E$53,"<>")+COUNTIFS('🎤 Webinars & Events'!$B$4:$B$53,B16,'🎤 Webinars & Events'!$E$4:$E$53,"<>")
A17: 14 | B17: =IF(C17="","","CAMP-"&TEXT(14,"000")) | Q17: =COUNTIFS('🎨 Creatives'!$B$4:$B$53,B17,'🎨 Creatives'!$E$4:$E$53,"<>")+COUNTIFS('🌐 Landing Pages'!$B$4:$B$53,B17,'🌐 Landing Pages'!$E$4:$E$53,"<>")+COUNTIFS('✍ Content Writing'!$B$4:$B$53,B17,'✍ Content Writing'!$E$4:$E$53,"<>")+COUNTIFS('🎁 Lead Magnets'!$B$4:$B$53,B17,'🎁 Lead Magnets'!$E$4:$E$53,"<>")+COUNTIFS('📧 Email Sequences'!$B$4:$B$53,B17,'📧 Email Sequences'!$E$4:$E$53,"<>")+COUNTIFS('📣 Ad Copy'!$B$4:$B$53,B17,'📣 Ad Copy'!$E$4:$E$53,"<>")+COUNTIFS('🔍 SEO'!$B$4:$B$53,B17,'🔍 SEO'!$E$4:$E$53,"<>")+COUNTIFS('🎤 Webinars & Events'!$B$4:$B$53,B17,'🎤 Webinars & Events'!$E$4:$E$53,"<>")
A18: 15 | B18: =IF(C18="","","CAMP-"&TEXT(15,"000")) | Q18: =COUNTIFS('🎨 Creatives'!$B$4:$B$53,B18,'🎨 Creatives'!$E$4:$E$53,"<>")+COUNTIFS('🌐 Landing Pages'!$B$4:$B$53,B18,'🌐 Landing Pages'!$E$4:$E$53,"<>")+COUNTIFS('✍ Content Writing'!$B$4:$B$53,B18,'✍ Content Writing'!$E$4:$E$53,"<>")+COUNTIFS('🎁 Lead Magnets'!$B$4:$B$53,B18,'🎁 Lead Magnets'!$E$4:$E$53,"<>")+COUNTIFS('📧 Email Sequences'!$B$4:$B$53,B18,'📧 Email Sequences'!$E$4:$E$53,"<>")+COUNTIFS('📣 Ad Copy'!$B$4:$B$53,B18,'📣 Ad Copy'!$E$4:$E$53,"<>")+COUNTIFS('🔍 SEO'!$B$4:$B$53,B18,'🔍 SEO'!$E$4:$E$53,"<>")+COUNTIFS('🎤 Webinars & Events'!$B$4:$B$53,B18,'🎤 Webinars & Events'!$E$4:$E$53,"<>")
A19: 16 | B19: =IF(C19="","","CAMP-"&TEXT(16,"000")) | Q19: =COUNTIFS('🎨 Creatives'!$B$4:$B$53,B19,'🎨 Creatives'!$E$4:$E$53,"<>")+COUNTIFS('🌐 Landing Pages'!$B$4:$B$53,B19,'🌐 Landing Pages'!$E$4:$E$53,"<>")+COUNTIFS('✍ Content Writing'!$B$4:$B$53,B19,'✍ Content Writing'!$E$4:$E$53,"<>")+COUNTIFS('🎁 Lead Magnets'!$B$4:$B$53,B19,'🎁 Lead Magnets'!$E$4:$E$53,"<>")+COUNTIFS('📧 Email Sequences'!$B$4:$B$53,B19,'📧 Email Sequences'!$E$4:$E$53,"<>")+COUNTIFS('📣 Ad Copy'!$B$4:$B$53,B19,'📣 Ad Copy'!$E$4:$E$53,"<>")+COUNTIFS('🔍 SEO'!$B$4:$B$53,B19,'🔍 SEO'!$E$4:$E$53,"<>")+COUNTIFS('🎤 Webinars & Events'!$B$4:$B$53,B19,'🎤 Webinars & Events'!$E$4:$E$53,"<>")
A20: 17 | B20: =IF(C20="","","CAMP-"&TEXT(17,"000")) | Q20: =COUNTIFS('🎨 Creatives'!$B$4:$B$53,B20,'🎨 Creatives'!$E$4:$E$53,"<>")+COUNTIFS('🌐 Landing Pages'!$B$4:$B$53,B20,'🌐 Landing Pages'!$E$4:$E$53,"<>")+COUNTIFS('✍ Content Writing'!$B$4:$B$53,B20,'✍ Content Writing'!$E$4:$E$53,"<>")+COUNTIFS('🎁 Lead Magnets'!$B$4:$B$53,B20,'🎁 Lead Magnets'!$E$4:$E$53,"<>")+COUNTIFS('📧 Email Sequences'!$B$4:$B$53,B20,'📧 Email Sequences'!$E$4:$E$53,"<>")+COUNTIFS('📣 Ad Copy'!$B$4:$B$53,B20,'📣 Ad Copy'!$E$4:$E$53,"<>")+COUNTIFS('🔍 SEO'!$B$4:$B$53,B20,'🔍 SEO'!$E$4:$E$53,"<>")+COUNTIFS('🎤 Webinars & Events'!$B$4:$B$53,B20,'🎤 Webinars & Events'!$E$4:$E$53,"<>")
A21: 18 | B21: =IF(C21="","","CAMP-"&TEXT(18,"000")) | Q21: =COUNTIFS('🎨 Creatives'!$B$4:$B$53,B21,'🎨 Creatives'!$E$4:$E$53,"<>")+COUNTIFS('🌐 Landing Pages'!$B$4:$B$53,B21,'🌐 Landing Pages'!$E$4:$E$53,"<>")+COUNTIFS('✍ Content Writing'!$B$4:$B$53,B21,'✍ Content Writing'!$E$4:$E$53,"<>")+COUNTIFS('🎁 Lead Magnets'!$B$4:$B$53,B21,'🎁 Lead Magnets'!$E$4:$E$53,"<>")+COUNTIFS('📧 Email Sequences'!$B$4:$B$53,B21,'📧 Email Sequences'!$E$4:$E$53,"<>")+COUNTIFS('📣 Ad Copy'!$B$4:$B$53,B21,'📣 Ad Copy'!$E$4:$E$53,"<>")+COUNTIFS('🔍 SEO'!$B$4:$B$53,B21,'🔍 SEO'!$E$4:$E$53,"<>")+COUNTIFS('🎤 Webinars & Events'!$B$4:$B$53,B21,'🎤 Webinars & Events'!$E$4:$E$53,"<>")
A22: 19 | B22: =IF(C22="","","CAMP-"&TEXT(19,"000")) | Q22: =COUNTIFS('🎨 Creatives'!$B$4:$B$53,B22,'🎨 Creatives'!$E$4:$E$53,"<>")+COUNTIFS('🌐 Landing Pages'!$B$4:$B$53,B22,'🌐 Landing Pages'!$E$4:$E$53,"<>")+COUNTIFS('✍ Content Writing'!$B$4:$B$53,B22,'✍ Content Writing'!$E$4:$E$53,"<>")+COUNTIFS('🎁 Lead Magnets'!$B$4:$B$53,B22,'🎁 Lead Magnets'!$E$4:$E$53,"<>")+COUNTIFS('📧 Email Sequences'!$B$4:$B$53,B22,'📧 Email Sequences'!$E$4:$E$53,"<>")+COUNTIFS('📣 Ad Copy'!$B$4:$B$53,B22,'📣 Ad Copy'!$E$4:$E$53,"<>")+COUNTIFS('🔍 SEO'!$B$4:$B$53,B22,'🔍 SEO'!$E$4:$E$53,"<>")+COUNTIFS('🎤 Webinars & Events'!$B$4:$B$53,B22,'🎤 Webinars & Events'!$E$4:$E$53,"<>")
A23: 20 | B23: =IF(C23="","","CAMP-"&TEXT(20,"000")) | Q23: =COUNTIFS('🎨 Creatives'!$B$4:$B$53,B23,'🎨 Creatives'!$E$4:$E$53,"<>")+COUNTIFS('🌐 Landing Pages'!$B$4:$B$53,B23,'🌐 Landing Pages'!$E$4:$E$53,"<>")+COUNTIFS('✍ Content Writing'!$B$4:$B$53,B23,'✍ Content Writing'!$E$4:$E$53,"<>")+COUNTIFS('🎁 Lead Magnets'!$B$4:$B$53,B23,'🎁 Lead Magnets'!$E$4:$E$53,"<>")+COUNTIFS('📧 Email Sequences'!$B$4:$B$53,B23,'📧 Email Sequences'!$E$4:$E$53,"<>")+COUNTIFS('📣 Ad Copy'!$B$4:$B$53,B23,'📣 Ad Copy'!$E$4:$E$53,"<>")+COUNTIFS('🔍 SEO'!$B$4:$B$53,B23,'🔍 SEO'!$E$4:$E$53,"<>")+COUNTIFS('🎤 Webinars & Events'!$B$4:$B$53,B23,'🎤 Webinars & Events'!$E$4:$E$53,"<>")
A24: 21 | B24: =IF(C24="","","CAMP-"&TEXT(21,"000")) | Q24: =COUNTIFS('🎨 Creatives'!$B$4:$B$53,B24,'🎨 Creatives'!$E$4:$E$53,"<>")+COUNTIFS('🌐 Landing Pages'!$B$4:$B$53,B24,'🌐 Landing Pages'!$E$4:$E$53,"<>")+COUNTIFS('✍ Content Writing'!$B$4:$B$53,B24,'✍ Content Writing'!$E$4:$E$53,"<>")+COUNTIFS('🎁 Lead Magnets'!$B$4:$B$53,B24,'🎁 Lead Magnets'!$E$4:$E$53,"<>")+COUNTIFS('📧 Email Sequences'!$B$4:$B$53,B24,'📧 Email Sequences'!$E$4:$E$53,"<>")+COUNTIFS('📣 Ad Copy'!$B$4:$B$53,B24,'📣 Ad Copy'!$E$4:$E$53,"<>")+COUNTIFS('🔍 SEO'!$B$4:$B$53,B24,'🔍 SEO'!$E$4:$E$53,"<>")+COUNTIFS('🎤 Webinars & Events'!$B$4:$B$53,B24,'🎤 Webinars & Events'!$E$4:$E$53,"<>")
A25: 22 | B25: =IF(C25="","","CAMP-"&TEXT(22,"000")) | Q25: =COUNTIFS('🎨 Creatives'!$B$4:$B$53,B25,'🎨 Creatives'!$E$4:$E$53,"<>")+COUNTIFS('🌐 Landing Pages'!$B$4:$B$53,B25,'🌐 Landing Pages'!$E$4:$E$53,"<>")+COUNTIFS('✍ Content Writing'!$B$4:$B$53,B25,'✍ Content Writing'!$E$4:$E$53,"<>")+COUNTIFS('🎁 Lead Magnets'!$B$4:$B$53,B25,'🎁 Lead Magnets'!$E$4:$E$53,"<>")+COUNTIFS('📧 Email Sequences'!$B$4:$B$53,B25,'📧 Email Sequences'!$E$4:$E$53,"<>")+COUNTIFS('📣 Ad Copy'!$B$4:$B$53,B25,'📣 Ad Copy'!$E$4:$E$53,"<>")+COUNTIFS('🔍 SEO'!$B$4:$B$53,B25,'🔍 SEO'!$E$4:$E$53,"<>")+COUNTIFS('🎤 Webinars & Events'!$B$4:$B$53,B25,'🎤 Webinars & Events'!$E$4:$E$53,"<>")
A26: 23 | B26: =IF(C26="","","CAMP-"&TEXT(23,"000")) | Q26: =COUNTIFS('🎨 Creatives'!$B$4:$B$53,B26,'🎨 Creatives'!$E$4:$E$53,"<>")+COUNTIFS('🌐 Landing Pages'!$B$4:$B$53,B26,'🌐 Landing Pages'!$E$4:$E$53,"<>")+COUNTIFS('✍ Content Writing'!$B$4:$B$53,B26,'✍ Content Writing'!$E$4:$E$53,"<>")+COUNTIFS('🎁 Lead Magnets'!$B$4:$B$53,B26,'🎁 Lead Magnets'!$E$4:$E$53,"<>")+COUNTIFS('📧 Email Sequences'!$B$4:$B$53,B26,'📧 Email Sequences'!$E$4:$E$53,"<>")+COUNTIFS('📣 Ad Copy'!$B$4:$B$53,B26,'📣 Ad Copy'!$E$4:$E$53,"<>")+COUNTIFS('🔍 SEO'!$B$4:$B$53,B26,'🔍 SEO'!$E$4:$E$53,"<>")+COUNTIFS('🎤 Webinars & Events'!$B$4:$B$53,B26,'🎤 Webinars & Events'!$E$4:$E$53,"<>")
A27: 24 | B27: =IF(C27="","","CAMP-"&TEXT(24,"000")) | Q27: =COUNTIFS('🎨 Creatives'!$B$4:$B$53,B27,'🎨 Creatives'!$E$4:$E$53,"<>")+COUNTIFS('🌐 Landing Pages'!$B$4:$B$53,B27,'🌐 Landing Pages'!$E$4:$E$53,"<>")+COUNTIFS('✍ Content Writing'!$B$4:$B$53,B27,'✍ Content Writing'!$E$4:$E$53,"<>")+COUNTIFS('🎁 Lead Magnets'!$B$4:$B$53,B27,'🎁 Lead Magnets'!$E$4:$E$53,"<>")+COUNTIFS('📧 Email Sequences'!$B$4:$B$53,B27,'📧 Email Sequences'!$E$4:$E$53,"<>")+COUNTIFS('📣 Ad Copy'!$B$4:$B$53,B27,'📣 Ad Copy'!$E$4:$E$53,"<>")+COUNTIFS('🔍 SEO'!$B$4:$B$53,B27,'🔍 SEO'!$E$4:$E$53,"<>")+COUNTIFS('🎤 Webinars & Events'!$B$4:$B$53,B27,'🎤 Webinars & Events'!$E$4:$E$53,"<>")
A28: 25 | B28: =IF(C28="","","CAMP-"&TEXT(25,"000")) | Q28: =COUNTIFS('🎨 Creatives'!$B$4:$B$53,B28,'🎨 Creatives'!$E$4:$E$53,"<>")+COUNTIFS('🌐 Landing Pages'!$B$4:$B$53,B28,'🌐 Landing Pages'!$E$4:$E$53,"<>")+COUNTIFS('✍ Content Writing'!$B$4:$B$53,B28,'✍ Content Writing'!$E$4:$E$53,"<>")+COUNTIFS('🎁 Lead Magnets'!$B$4:$B$53,B28,'🎁 Lead Magnets'!$E$4:$E$53,"<>")+COUNTIFS('📧 Email Sequences'!$B$4:$B$53,B28,'📧 Email Sequences'!$E$4:$E$53,"<>")+COUNTIFS('📣 Ad Copy'!$B$4:$B$53,B28,'📣 Ad Copy'!$E$4:$E$53,"<>")+COUNTIFS('🔍 SEO'!$B$4:$B$53,B28,'🔍 SEO'!$E$4:$E$53,"<>")+COUNTIFS('🎤 Webinars & Events'!$B$4:$B$53,B28,'🎤 Webinars & Events'!$E$4:$E$53,"<>")
A29: 26 | B29: =IF(C29="","","CAMP-"&TEXT(26,"000")) | Q29: =COUNTIFS('🎨 Creatives'!$B$4:$B$53,B29,'🎨 Creatives'!$E$4:$E$53,"<>")+COUNTIFS('🌐 Landing Pages'!$B$4:$B$53,B29,'🌐 Landing Pages'!$E$4:$E$53,"<>")+COUNTIFS('✍ Content Writing'!$B$4:$B$53,B29,'✍ Content Writing'!$E$4:$E$53,"<>")+COUNTIFS('🎁 Lead Magnets'!$B$4:$B$53,B29,'🎁 Lead Magnets'!$E$4:$E$53,"<>")+COUNTIFS('📧 Email Sequences'!$B$4:$B$53,B29,'📧 Email Sequences'!$E$4:$E$53,"<>")+COUNTIFS('📣 Ad Copy'!$B$4:$B$53,B29,'📣 Ad Copy'!$E$4:$E$53,"<>")+COUNTIFS('🔍 SEO'!$B$4:$B$53,B29,'🔍 SEO'!$E$4:$E$53,"<>")+COUNTIFS('🎤 Webinars & Events'!$B$4:$B$53,B29,'🎤 Webinars & Events'!$E$4:$E$53,"<>")
A30: 27 | B30: =IF(C30="","","CAMP-"&TEXT(27,"000")) | Q30: =COUNTIFS('🎨 Creatives'!$B$4:$B$53,B30,'🎨 Creatives'!$E$4:$E$53,"<>")+COUNTIFS('🌐 Landing Pages'!$B$4:$B$53,B30,'🌐 Landing Pages'!$E$4:$E$53,"<>")+COUNTIFS('✍ Content Writing'!$B$4:$B$53,B30,'✍ Content Writing'!$E$4:$E$53,"<>")+COUNTIFS('🎁 Lead Magnets'!$B$4:$B$53,B30,'🎁 Lead Magnets'!$E$4:$E$53,"<>")+COUNTIFS('📧 Email Sequences'!$B$4:$B$53,B30,'📧 Email Sequences'!$E$4:$E$53,"<>")+COUNTIFS('📣 Ad Copy'!$B$4:$B$53,B30,'📣 Ad Copy'!$E$4:$E$53,"<>")+COUNTIFS('🔍 SEO'!$B$4:$B$53,B30,'🔍 SEO'!$E$4:$E$53,"<>")+COUNTIFS('🎤 Webinars & Events'!$B$4:$B$53,B30,'🎤 Webinars & Events'!$E$4:$E$53,"<>")
A31: 28 | B31: =IF(C31="","","CAMP-"&TEXT(28,"000")) | Q31: =COUNTIFS('🎨 Creatives'!$B$4:$B$53,B31,'🎨 Creatives'!$E$4:$E$53,"<>")+COUNTIFS('🌐 Landing Pages'!$B$4:$B$53,B31,'🌐 Landing Pages'!$E$4:$E$53,"<>")+COUNTIFS('✍ Content Writing'!$B$4:$B$53,B31,'✍ Content Writing'!$E$4:$E$53,"<>")+COUNTIFS('🎁 Lead Magnets'!$B$4:$B$53,B31,'🎁 Lead Magnets'!$E$4:$E$53,"<>")+COUNTIFS('📧 Email Sequences'!$B$4:$B$53,B31,'📧 Email Sequences'!$E$4:$E$53,"<>")+COUNTIFS('📣 Ad Copy'!$B$4:$B$53,B31,'📣 Ad Copy'!$E$4:$E$53,"<>")+COUNTIFS('🔍 SEO'!$B$4:$B$53,B31,'🔍 SEO'!$E$4:$E$53,"<>")+COUNTIFS('🎤 Webinars & Events'!$B$4:$B$53,B31,'🎤 Webinars & Events'!$E$4:$E$53,"<>")
A32: 29 | B32: =IF(C32="","","CAMP-"&TEXT(29,"000")) | Q32: =COUNTIFS('🎨 Creatives'!$B$4:$B$53,B32,'🎨 Creatives'!$E$4:$E$53,"<>")+COUNTIFS('🌐 Landing Pages'!$B$4:$B$53,B32,'🌐 Landing Pages'!$E$4:$E$53,"<>")+COUNTIFS('✍ Content Writing'!$B$4:$B$53,B32,'✍ Content Writing'!$E$4:$E$53,"<>")+COUNTIFS('🎁 Lead Magnets'!$B$4:$B$53,B32,'🎁 Lead Magnets'!$E$4:$E$53,"<>")+COUNTIFS('📧 Email Sequences'!$B$4:$B$53,B32,'📧 Email Sequences'!$E$4:$E$53,"<>")+COUNTIFS('📣 Ad Copy'!$B$4:$B$53,B32,'📣 Ad Copy'!$E$4:$E$53,"<>")+COUNTIFS('🔍 SEO'!$B$4:$B$53,B32,'🔍 SEO'!$E$4:$E$53,"<>")+COUNTIFS('🎤 Webinars & Events'!$B$4:$B$53,B32,'🎤 Webinars & Events'!$E$4:$E$53,"<>")
A33: 30 | B33: =IF(C33="","","CAMP-"&TEXT(30,"000")) | Q33: =COUNTIFS('🎨 Creatives'!$B$4:$B$53,B33,'🎨 Creatives'!$E$4:$E$53,"<>")+COUNTIFS('🌐 Landing Pages'!$B$4:$B$53,B33,'🌐 Landing Pages'!$E$4:$E$53,"<>")+COUNTIFS('✍ Content Writing'!$B$4:$B$53,B33,'✍ Content Writing'!$E$4:$E$53,"<>")+COUNTIFS('🎁 Lead Magnets'!$B$4:$B$53,B33,'🎁 Lead Magnets'!$E$4:$E$53,"<>")+COUNTIFS('📧 Email Sequences'!$B$4:$B$53,B33,'📧 Email Sequences'!$E$4:$E$53,"<>")+COUNTIFS('📣 Ad Copy'!$B$4:$B$53,B33,'📣 Ad Copy'!$E$4:$E$53,"<>")+COUNTIFS('🔍 SEO'!$B$4:$B$53,B33,'🔍 SEO'!$E$4:$E$53,"<>")+COUNTIFS('🎤 Webinars & Events'!$B$4:$B$53,B33,'🎤 Webinars & Events'!$E$4:$E$53,"<>")
A34: 31 | B34: =IF(C34="","","CAMP-"&TEXT(31,"000")) | Q34: =COUNTIFS('🎨 Creatives'!$B$4:$B$53,B34,'🎨 Creatives'!$E$4:$E$53,"<>")+COUNTIFS('🌐 Landing Pages'!$B$4:$B$53,B34,'🌐 Landing Pages'!$E$4:$E$53,"<>")+COUNTIFS('✍ Content Writing'!$B$4:$B$53,B34,'✍ Content Writing'!$E$4:$E$53,"<>")+COUNTIFS('🎁 Lead Magnets'!$B$4:$B$53,B34,'🎁 Lead Magnets'!$E$4:$E$53,"<>")+COUNTIFS('📧 Email Sequences'!$B$4:$B$53,B34,'📧 Email Sequences'!$E$4:$E$53,"<>")+COUNTIFS('📣 Ad Copy'!$B$4:$B$53,B34,'📣 Ad Copy'!$E$4:$E$53,"<>")+COUNTIFS('🔍 SEO'!$B$4:$B$53,B34,'🔍 SEO'!$E$4:$E$53,"<>")+COUNTIFS('🎤 Webinars & Events'!$B$4:$B$53,B34,'🎤 Webinars & Events'!$E$4:$E$53,"<>")
A35: 32 | B35: =IF(C35="","","CAMP-"&TEXT(32,"000")) | Q35: =COUNTIFS('🎨 Creatives'!$B$4:$B$53,B35,'🎨 Creatives'!$E$4:$E$53,"<>")+COUNTIFS('🌐 Landing Pages'!$B$4:$B$53,B35,'🌐 Landing Pages'!$E$4:$E$53,"<>")+COUNTIFS('✍ Content Writing'!$B$4:$B$53,B35,'✍ Content Writing'!$E$4:$E$53,"<>")+COUNTIFS('🎁 Lead Magnets'!$B$4:$B$53,B35,'🎁 Lead Magnets'!$E$4:$E$53,"<>")+COUNTIFS('📧 Email Sequences'!$B$4:$B$53,B35,'📧 Email Sequences'!$E$4:$E$53,"<>")+COUNTIFS('📣 Ad Copy'!$B$4:$B$53,B35,'📣 Ad Copy'!$E$4:$E$53,"<>")+COUNTIFS('🔍 SEO'!$B$4:$B$53,B35,'🔍 SEO'!$E$4:$E$53,"<>")+COUNTIFS('🎤 Webinars & Events'!$B$4:$B$53,B35,'🎤 Webinars & Events'!$E$4:$E$53,"<>")
A36: 33 | B36: =IF(C36="","","CAMP-"&TEXT(33,"000")) | Q36: =COUNTIFS('🎨 Creatives'!$B$4:$B$53,B36,'🎨 Creatives'!$E$4:$E$53,"<>")+COUNTIFS('🌐 Landing Pages'!$B$4:$B$53,B36,'🌐 Landing Pages'!$E$4:$E$53,"<>")+COUNTIFS('✍ Content Writing'!$B$4:$B$53,B36,'✍ Content Writing'!$E$4:$E$53,"<>")+COUNTIFS('🎁 Lead Magnets'!$B$4:$B$53,B36,'🎁 Lead Magnets'!$E$4:$E$53,"<>")+COUNTIFS('📧 Email Sequences'!$B$4:$B$53,B36,'📧 Email Sequences'!$E$4:$E$53,"<>")+COUNTIFS('📣 Ad Copy'!$B$4:$B$53,B36,'📣 Ad Copy'!$E$4:$E$53,"<>")+COUNTIFS('🔍 SEO'!$B$4:$B$53,B36,'🔍 SEO'!$E$4:$E$53,"<>")+COUNTIFS('🎤 Webinars & Events'!$B$4:$B$53,B36,'🎤 Webinars & Events'!$E$4:$E$53,"<>")
A37: 34 | B37: =IF(C37="","","CAMP-"&TEXT(34,"000")) | Q37: =COUNTIFS('🎨 Creatives'!$B$4:$B$53,B37,'🎨 Creatives'!$E$4:$E$53,"<>")+COUNTIFS('🌐 Landing Pages'!$B$4:$B$53,B37,'🌐 Landing Pages'!$E$4:$E$53,"<>")+COUNTIFS('✍ Content Writing'!$B$4:$B$53,B37,'✍ Content Writing'!$E$4:$E$53,"<>")+COUNTIFS('🎁 Lead Magnets'!$B$4:$B$53,B37,'🎁 Lead Magnets'!$E$4:$E$53,"<>")+COUNTIFS('📧 Email Sequences'!$B$4:$B$53,B37,'📧 Email Sequences'!$E$4:$E$53,"<>")+COUNTIFS('📣 Ad Copy'!$B$4:$B$53,B37,'📣 Ad Copy'!$E$4:$E$53,"<>")+COUNTIFS('🔍 SEO'!$B$4:$B$53,B37,'🔍 SEO'!$E$4:$E$53,"<>")+COUNTIFS('🎤 Webinars & Events'!$B$4:$B$53,B37,'🎤 Webinars & Events'!$E$4:$E$53,"<>")
A38: 35 | B38: =IF(C38="","","CAMP-"&TEXT(35,"000")) | Q38: =COUNTIFS('🎨 Creatives'!$B$4:$B$53,B38,'🎨 Creatives'!$E$4:$E$53,"<>")+COUNTIFS('🌐 Landing Pages'!$B$4:$B$53,B38,'🌐 Landing Pages'!$E$4:$E$53,"<>")+COUNTIFS('✍ Content Writing'!$B$4:$B$53,B38,'✍ Content Writing'!$E$4:$E$53,"<>")+COUNTIFS('🎁 Lead Magnets'!$B$4:$B$53,B38,'🎁 Lead Magnets'!$E$4:$E$53,"<>")+COUNTIFS('📧 Email Sequences'!$B$4:$B$53,B38,'📧 Email Sequences'!$E$4:$E$53,"<>")+COUNTIFS('📣 Ad Copy'!$B$4:$B$53,B38,'📣 Ad Copy'!$E$4:$E$53,"<>")+COUNTIFS('🔍 SEO'!$B$4:$B$53,B38,'🔍 SEO'!$E$4:$E$53,"<>")+COUNTIFS('🎤 Webinars & Events'!$B$4:$B$53,B38,'🎤 Webinars & Events'!$E$4:$E$53,"<>")
A39: 36 | B39: =IF(C39="","","CAMP-"&TEXT(36,"000")) | Q39: =COUNTIFS('🎨 Creatives'!$B$4:$B$53,B39,'🎨 Creatives'!$E$4:$E$53,"<>")+COUNTIFS('🌐 Landing Pages'!$B$4:$B$53,B39,'🌐 Landing Pages'!$E$4:$E$53,"<>")+COUNTIFS('✍ Content Writing'!$B$4:$B$53,B39,'✍ Content Writing'!$E$4:$E$53,"<>")+COUNTIFS('🎁 Lead Magnets'!$B$4:$B$53,B39,'🎁 Lead Magnets'!$E$4:$E$53,"<>")+COUNTIFS('📧 Email Sequences'!$B$4:$B$53,B39,'📧 Email Sequences'!$E$4:$E$53,"<>")+COUNTIFS('📣 Ad Copy'!$B$4:$B$53,B39,'📣 Ad Copy'!$E$4:$E$53,"<>")+COUNTIFS('🔍 SEO'!$B$4:$B$53,B39,'🔍 SEO'!$E$4:$E$53,"<>")+COUNTIFS('🎤 Webinars & Events'!$B$4:$B$53,B39,'🎤 Webinars & Events'!$E$4:$E$53,"<>")
A40: 37 | B40: =IF(C40="","","CAMP-"&TEXT(37,"000")) | Q40: =COUNTIFS('🎨 Creatives'!$B$4:$B$53,B40,'🎨 Creatives'!$E$4:$E$53,"<>")+COUNTIFS('🌐 Landing Pages'!$B$4:$B$53,B40,'🌐 Landing Pages'!$E$4:$E$53,"<>")+COUNTIFS('✍ Content Writing'!$B$4:$B$53,B40,'✍ Content Writing'!$E$4:$E$53,"<>")+COUNTIFS('🎁 Lead Magnets'!$B$4:$B$53,B40,'🎁 Lead Magnets'!$E$4:$E$53,"<>")+COUNTIFS('📧 Email Sequences'!$B$4:$B$53,B40,'📧 Email Sequences'!$E$4:$E$53,"<>")+COUNTIFS('📣 Ad Copy'!$B$4:$B$53,B40,'📣 Ad Copy'!$E$4:$E$53,"<>")+COUNTIFS('🔍 SEO'!$B$4:$B$53,B40,'🔍 SEO'!$E$4:$E$53,"<>")+COUNTIFS('🎤 Webinars & Events'!$B$4:$B$53,B40,'🎤 Webinars & Events'!$E$4:$E$53,"<>")
...

Sheet 🎨 Creatives
A1: SolidPro — Creatives Tracker (Graphic Design & Video)
A2: Link each row to a Campaign ID from the Campaign Master sheet | * = Mandatory
A3: S.No | B3: Campaign ID * | C3: Asset ID | D3: Vertical * | E3: Asset Name / Title * | F3: Content Type | G3: Asset Type | H3: Format / Size | I3: Platform | J3: Campaign / Theme | K3: Brief / Description | L3: Owner * | M3: Support | N3: Requested By | O3: Brief Date | P3: Due Date * | Q3: Pub / Post Date * | R3: Priority | S3: Status | T3: Approved by Project Head | U3: Approved by Manager | V3: Final File / URL Link | W3: Revision # | X3: Feedback / Notes | Y3: Archived?
A4: 1 | C4: =IF(E4="","",UPPER(LEFT(D4,3))&"-"&TEXT(1,"000"))
A5: 2 | C5: =IF(E5="","",UPPER(LEFT(D5,3))&"-"&TEXT(2,"000"))
A6: 3 | C6: =IF(E6="","",UPPER(LEFT(D6,3))&"-"&TEXT(3,"000"))
A7: 4 | C7: =IF(E7="","",UPPER(LEFT(D7,3))&"-"&TEXT(4,"000"))
A8: 5 | C8: =IF(E8="","",UPPER(LEFT(D8,3))&"-"&TEXT(5,"000"))
A9: 6 | C9: =IF(E9="","",UPPER(LEFT(D9,3))&"-"&TEXT(6,"000"))
A10: 7 | C10: =IF(E10="","",UPPER(LEFT(D10,3))&"-"&TEXT(7,"000"))
A11: 8 | C11: =IF(E11="","",UPPER(LEFT(D11,3))&"-"&TEXT(8,"000"))
A12: 9 | C12: =IF(E12="","",UPPER(LEFT(D12,3))&"-"&TEXT(9,"000"))
A13: 10 | C13: =IF(E13="","",UPPER(LEFT(D13,3))&"-"&TEXT(10,"000"))
A14: 11 | C14: =IF(E14="","",UPPER(LEFT(D14,3))&"-"&TEXT(11,"000"))
A15: 12 | C15: =IF(E15="","",UPPER(LEFT(D15,3))&"-"&TEXT(12,"000"))
A16: 13 | C16: =IF(E16="","",UPPER(LEFT(D16,3))&"-"&TEXT(13,"000"))
A17: 14 | C17: =IF(E17="","",UPPER(LEFT(D17,3))&"-"&TEXT(14,"000"))
A18: 15 | C18: =IF(E18="","",UPPER(LEFT(D18,3))&"-"&TEXT(15,"000"))
A19: 16 | C19: =IF(E19="","",UPPER(LEFT(D19,3))&"-"&TEXT(16,"000"))
A20: 17 | C20: =IF(E20="","",UPPER(LEFT(D20,3))&"-"&TEXT(17,"000"))
A21: 18 | C21: =IF(E21="","",UPPER(LEFT(D21,3))&"-"&TEXT(18,"000"))
A22: 19 | C22: =IF(E22="","",UPPER(LEFT(D22,3))&"-"&TEXT(19,"000"))
A23: 20 | C23: =IF(E23="","",UPPER(LEFT(D23,3))&"-"&TEXT(20,"000"))
A24: 21 | C24: =IF(E24="","",UPPER(LEFT(D24,3))&"-"&TEXT(21,"000"))
A25: 22 | C25: =IF(E25="","",UPPER(LEFT(D25,3))&"-"&TEXT(22,"000"))
A26: 23 | C26: =IF(E26="","",UPPER(LEFT(D26,3))&"-"&TEXT(23,"000"))
A27: 24 | C27: =IF(E27="","",UPPER(LEFT(D27,3))&"-"&TEXT(24,"000"))
A28: 25 | C28: =IF(E28="","",UPPER(LEFT(D28,3))&"-"&TEXT(25,"000"))
A29: 26 | C29: =IF(E29="","",UPPER(LEFT(D29,3))&"-"&TEXT(26,"000"))
A30: 27 | C30: =IF(E30="","",UPPER(LEFT(D30,3))&"-"&TEXT(27,"000"))
A31: 28 | C31: =IF(E31="","",UPPER(LEFT(D31,3))&"-"&TEXT(28,"000"))
A32: 29 | C32: =IF(E32="","",UPPER(LEFT(D32,3))&"-"&TEXT(29,"000"))
A33: 30 | C33: =IF(E33="","",UPPER(LEFT(D33,3))&"-"&TEXT(30,"000"))
A34: 31 | C34: =IF(E34="","",UPPER(LEFT(D34,3))&"-"&TEXT(31,"000"))
A35: 32 | C35: =IF(E35="","",UPPER(LEFT(D35,3))&"-"&TEXT(32,"000"))
A36: 33 | C36: =IF(E36="","",UPPER(LEFT(D36,3))&"-"&TEXT(33,"000"))
A37: 34 | C37: =IF(E37="","",UPPER(LEFT(D37,3))&"-"&TEXT(34,"000"))
A38: 35 | C38: =IF(E38="","",UPPER(LEFT(D38,3))&"-"&TEXT(35,"000"))
A39: 36 | C39: =IF(E39="","",UPPER(LEFT(D39,3))&"-"&TEXT(36,"000"))
A40: 37 | C40: =IF(E40="","",UPPER(LEFT(D40,3))&"-"&TEXT(37,"000"))
...

Sheet 🌐 Landing Pages
A1: SolidPro — Landing Pages Tracker
A2: Link each row to a Campaign ID from the Campaign Master sheet | * = Mandatory
A3: S.No | B3: Campaign ID * | C3: Asset ID | D3: Vertical * | E3: Asset Name / Title * | F3: Page URL / Slug | G3: Page Goal | H3: Landing Page Type | I3: Linked Creative Asset ID | J3: Linked Lead Magnet ID | K3: Linked Email Seq ID | L3: CTA Text | M3: Form Fields Required | N3: SEO Title | O3: Meta Description | P3: Dev Owner (SS) | Q3: Content Writer | R3: Design Asset ID | S3: UTM Parameters | T3: A/B Test? | U3: Conversion Goal | V3: Owner * | W3: Support | X3: Requested By | Y3: Brief Date | Z3: Due Date * | AA3: Pub / Post Date * | AB3: Priority | AC3: Status | AD3: Approved by Project Head | AE3: Approved by Manager | AF3: Final File / URL Link | AG3: Revision # | AH3: Feedback / Notes | AI3: Archived?
A4: 1 | C4: =IF(E4="","",UPPER(LEFT(D4,3))&"-"&TEXT(1,"000"))
A5: 2 | C5: =IF(E5="","",UPPER(LEFT(D5,3))&"-"&TEXT(2,"000"))
A6: 3 | C6: =IF(E6="","",UPPER(LEFT(D6,3))&"-"&TEXT(3,"000"))
A7: 4 | C7: =IF(E7="","",UPPER(LEFT(D7,3))&"-"&TEXT(4,"000"))
A8: 5 | C8: =IF(E8="","",UPPER(LEFT(D8,3))&"-"&TEXT(5,"000"))
A9: 6 | C9: =IF(E9="","",UPPER(LEFT(D9,3))&"-"&TEXT(6,"000"))
A10: 7 | C10: =IF(E10="","",UPPER(LEFT(D10,3))&"-"&TEXT(7,"000"))
A11: 8 | C11: =IF(E11="","",UPPER(LEFT(D11,3))&"-"&TEXT(8,"000"))
A12: 9 | C12: =IF(E12="","",UPPER(LEFT(D12,3))&"-"&TEXT(9,"000"))
A13: 10 | C13: =IF(E13="","",UPPER(LEFT(D13,3))&"-"&TEXT(10,"000"))
A14: 11 | C14: =IF(E14="","",UPPER(LEFT(D14,3))&"-"&TEXT(11,"000"))
A15: 12 | C15: =IF(E15="","",UPPER(LEFT(D15,3))&"-"&TEXT(12,"000"))
A16: 13 | C16: =IF(E16="","",UPPER(LEFT(D16,3))&"-"&TEXT(13,"000"))
A17: 14 | C17: =IF(E17="","",UPPER(LEFT(D17,3))&"-"&TEXT(14,"000"))
A18: 15 | C18: =IF(E18="","",UPPER(LEFT(D18,3))&"-"&TEXT(15,"000"))
A19: 16 | C19: =IF(E19="","",UPPER(LEFT(D19,3))&"-"&TEXT(16,"000"))
A20: 17 | C20: =IF(E20="","",UPPER(LEFT(D20,3))&"-"&TEXT(17,"000"))
A21: 18 | C21: =IF(E21="","",UPPER(LEFT(D21,3))&"-"&TEXT(18,"000"))
A22: 19 | C22: =IF(E22="","",UPPER(LEFT(D22,3))&"-"&TEXT(19,"000"))
A23: 20 | C23: =IF(E23="","",UPPER(LEFT(D23,3))&"-"&TEXT(20,"000"))
A24: 21 | C24: =IF(E24="","",UPPER(LEFT(D24,3))&"-"&TEXT(21,"000"))
A25: 22 | C25: =IF(E25="","",UPPER(LEFT(D25,3))&"-"&TEXT(22,"000"))
A26: 23 | C26: =IF(E26="","",UPPER(LEFT(D26,3))&"-"&TEXT(23,"000"))
A27: 24 | C27: =IF(E27="","",UPPER(LEFT(D27,3))&"-"&TEXT(24,"000"))
A28: 25 | C28: =IF(E28="","",UPPER(LEFT(D28,3))&"-"&TEXT(25,"000"))
A29: 26 | C29: =IF(E29="","",UPPER(LEFT(D29,3))&"-"&TEXT(26,"000"))
A30: 27 | C30: =IF(E30="","",UPPER(LEFT(D30,3))&"-"&TEXT(27,"000"))
A31: 28 | C31: =IF(E31="","",UPPER(LEFT(D31,3))&"-"&TEXT(28,"000"))
A32: 29 | C32: =IF(E32="","",UPPER(LEFT(D32,3))&"-"&TEXT(29,"000"))
A33: 30 | C33: =IF(E33="","",UPPER(LEFT(D33,3))&"-"&TEXT(30,"000"))
A34: 31 | C34: =IF(E34="","",UPPER(LEFT(D34,3))&"-"&TEXT(31,"000"))
A35: 32 | C35: =IF(E35="","",UPPER(LEFT(D35,3))&"-"&TEXT(32,"000"))
A36: 33 | C36: =IF(E36="","",UPPER(LEFT(D36,3))&"-"&TEXT(33,"000"))
A37: 34 | C37: =IF(E37="","",UPPER(LEFT(D37,3))&"-"&TEXT(34,"000"))
A38: 35 | C38: =IF(E38="","",UPPER(LEFT(D38,3))&"-"&TEXT(35,"000"))
A39: 36 | C39: =IF(E39="","",UPPER(LEFT(D39,3))&"-"&TEXT(36,"000"))
A40: 37 | C40: =IF(E40="","",UPPER(LEFT(D40,3))&"-"&TEXT(37,"000"))
...

Sheet ✍ Content Writing
A1: SolidPro — Content Writing Tracker
A2: Link each row to a Campaign ID from the Campaign Master sheet | * = Mandatory
A3: S.No | B3: Campaign ID * | C3: Asset ID | D3: Vertical * | E3: Asset Name / Title * | F3: Content Format | G3: Topic / Working Title | H3: Target Keyword(s) | I3: Word Count (Target) | J3: Audience Persona | K3: Funnel Stage | L3: Linked Asset IDs | M3: Linked Landing Page ID | N3: Tone of Voice | O3: References / Resources | P3: Draft Link | Q3: SEO Optimised? | R3: CMS Published? | S3: Owner * | T3: Support | U3: Requested By | V3: Brief Date | W3: Due Date * | X3: Pub / Post Date * | Y3: Priority | Z3: Status | AA3: Approved by Project Head | AB3: Approved by Manager | AC3: Final File / URL Link | AD3: Revision # | AE3: Feedback / Notes | AF3: Archived?
A4: 1 | C4: =IF(E4="","",UPPER(LEFT(D4,3))&"-"&TEXT(1,"000"))
A5: 2 | C5: =IF(E5="","",UPPER(LEFT(D5,3))&"-"&TEXT(2,"000"))
A6: 3 | C6: =IF(E6="","",UPPER(LEFT(D6,3))&"-"&TEXT(3,"000"))
A7: 4 | C7: =IF(E7="","",UPPER(LEFT(D7,3))&"-"&TEXT(4,"000"))
A8: 5 | C8: =IF(E8="","",UPPER(LEFT(D8,3))&"-"&TEXT(5,"000"))
A9: 6 | C9: =IF(E9="","",UPPER(LEFT(D9,3))&"-"&TEXT(6,"000"))
A10: 7 | C10: =IF(E10="","",UPPER(LEFT(D10,3))&"-"&TEXT(7,"000"))
A11: 8 | C11: =IF(E11="","",UPPER(LEFT(D11,3))&"-"&TEXT(8,"000"))
A12: 9 | C12: =IF(E12="","",UPPER(LEFT(D12,3))&"-"&TEXT(9,"000"))
A13: 10 | C13: =IF(E13="","",UPPER(LEFT(D13,3))&"-"&TEXT(10,"000"))
A14: 11 | C14: =IF(E14="","",UPPER(LEFT(D14,3))&"-"&TEXT(11,"000"))
A15: 12 | C15: =IF(E15="","",UPPER(LEFT(D15,3))&"-"&TEXT(12,"000"))
A16: 13 | C16: =IF(E16="","",UPPER(LEFT(D16,3))&"-"&TEXT(13,"000"))
A17: 14 | C17: =IF(E17="","",UPPER(LEFT(D17,3))&"-"&TEXT(14,"000"))
A18: 15 | C18: =IF(E18="","",UPPER(LEFT(D18,3))&"-"&TEXT(15,"000"))
A19: 16 | C19: =IF(E19="","",UPPER(LEFT(D19,3))&"-"&TEXT(16,"000"))
A20: 17 | C20: =IF(E20="","",UPPER(LEFT(D20,3))&"-"&TEXT(17,"000"))
A21: 18 | C21: =IF(E21="","",UPPER(LEFT(D21,3))&"-"&TEXT(18,"000"))
A22: 19 | C22: =IF(E22="","",UPPER(LEFT(D22,3))&"-"&TEXT(19,"000"))
A23: 20 | C23: =IF(E23="","",UPPER(LEFT(D23,3))&"-"&TEXT(20,"000"))
A24: 21 | C24: =IF(E24="","",UPPER(LEFT(D24,3))&"-"&TEXT(21,"000"))
A25: 22 | C25: =IF(E25="","",UPPER(LEFT(D25,3))&"-"&TEXT(22,"000"))
A26: 23 | C26: =IF(E26="","",UPPER(LEFT(D26,3))&"-"&TEXT(23,"000"))
A27: 24 | C27: =IF(E27="","",UPPER(LEFT(D27,3))&"-"&TEXT(24,"000"))
A28: 25 | C28: =IF(E28="","",UPPER(LEFT(D28,3))&"-"&TEXT(25,"000"))
A29: 26 | C29: =IF(E29="","",UPPER(LEFT(D29,3))&"-"&TEXT(26,"000"))
A30: 27 | C30: =IF(E30="","",UPPER(LEFT(D30,3))&"-"&TEXT(27,"000"))
A31: 28 | C31: =IF(E31="","",UPPER(LEFT(D31,3))&"-"&TEXT(28,"000"))
A32: 29 | C32: =IF(E32="","",UPPER(LEFT(D32,3))&"-"&TEXT(29,"000"))
A33: 30 | C33: =IF(E33="","",UPPER(LEFT(D33,3))&"-"&TEXT(30,"000"))
A34: 31 | C34: =IF(E34="","",UPPER(LEFT(D34,3))&"-"&TEXT(31,"000"))
A35: 32 | C35: =IF(E35="","",UPPER(LEFT(D35,3))&"-"&TEXT(32,"000"))
A36: 33 | C36: =IF(E36="","",UPPER(LEFT(D36,3))&"-"&TEXT(33,"000"))
A37: 34 | C37: =IF(E37="","",UPPER(LEFT(D37,3))&"-"&TEXT(34,"000"))
A38: 35 | C38: =IF(E38="","",UPPER(LEFT(D38,3))&"-"&TEXT(35,"000"))
A39: 36 | C39: =IF(E39="","",UPPER(LEFT(D39,3))&"-"&TEXT(36,"000"))
A40: 37 | C40: =IF(E40="","",UPPER(LEFT(D40,3))&"-"&TEXT(37,"000"))
...

Sheet 🎁 Lead Magnets
A1: SolidPro — Lead Magnets Tracker (Assessments, PDFs, Tools)
A2: Link each row to a Campaign ID from the Campaign Master sheet | * = Mandatory
A3: S.No | B3: Campaign ID * | C3: Asset ID | D3: Vertical * | E3: Asset Name / Title * | F3: Lead Magnet Type | G3: Topic / Title | H3: Format | I3: Target Persona | J3: Funnel Stage | K3: Linked Landing Page ID | L3: Linked Content ID | M3: Content Writer | N3: Designer | O3: No. of Pages / Q's | P3: Gating? (Form?) | Q3: Download / Access Link | R3: Lead Data Goes To | S3: Results / Outcomes Defined? | T3: Owner * | U3: Support | V3: Requested By | W3: Brief Date | X3: Due Date * | Y3: Pub / Post Date * | Z3: Priority | AA3: Status | AB3: Approved by Project Head | AC3: Approved by Manager | AD3: Final File / URL Link | AE3: Revision # | AF3: Feedback / Notes | AG3: Archived?
A4: 1 | C4: =IF(E4="","",UPPER(LEFT(D4,3))&"-"&TEXT(1,"000"))
A5: 2 | C5: =IF(E5="","",UPPER(LEFT(D5,3))&"-"&TEXT(2,"000"))
A6: 3 | C6: =IF(E6="","",UPPER(LEFT(D6,3))&"-"&TEXT(3,"000"))
A7: 4 | C7: =IF(E7="","",UPPER(LEFT(D7,3))&"-"&TEXT(4,"000"))
A8: 5 | C8: =IF(E8="","",UPPER(LEFT(D8,3))&"-"&TEXT(5,"000"))
A9: 6 | C9: =IF(E9="","",UPPER(LEFT(D9,3))&"-"&TEXT(6,"000"))
A10: 7 | C10: =IF(E10="","",UPPER(LEFT(D10,3))&"-"&TEXT(7,"000"))
A11: 8 | C11: =IF(E11="","",UPPER(LEFT(D11,3))&"-"&TEXT(8,"000"))
A12: 9 | C12: =IF(E12="","",UPPER(LEFT(D12,3))&"-"&TEXT(9,"000"))
A13: 10 | C13: =IF(E13="","",UPPER(LEFT(D13,3))&"-"&TEXT(10,"000"))
A14: 11 | C14: =IF(E14="","",UPPER(LEFT(D14,3))&"-"&TEXT(11,"000"))
A15: 12 | C15: =IF(E15="","",UPPER(LEFT(D15,3))&"-"&TEXT(12,"000"))
A16: 13 | C16: =IF(E16="","",UPPER(LEFT(D16,3))&"-"&TEXT(13,"000"))
A17: 14 | C17: =IF(E17="","",UPPER(LEFT(D17,3))&"-"&TEXT(14,"000"))
A18: 15 | C18: =IF(E18="","",UPPER(LEFT(D18,3))&"-"&TEXT(15,"000"))
A19: 16 | C19: =IF(E19="","",UPPER(LEFT(D19,3))&"-"&TEXT(16,"000"))
A20: 17 | C20: =IF(E20="","",UPPER(LEFT(D20,3))&"-"&TEXT(17,"000"))
A21: 18 | C21: =IF(E21="","",UPPER(LEFT(D21,3))&"-"&TEXT(18,"000"))
A22: 19 | C22: =IF(E22="","",UPPER(LEFT(D22,3))&"-"&TEXT(19,"000"))
A23: 20 | C23: =IF(E23="","",UPPER(LEFT(D23,3))&"-"&TEXT(20,"000"))
A24: 21 | C24: =IF(E24="","",UPPER(LEFT(D24,3))&"-"&TEXT(21,"000"))
A25: 22 | C25: =IF(E25="","",UPPER(LEFT(D25,3))&"-"&TEXT(22,"000"))
A26: 23 | C26: =IF(E26="","",UPPER(LEFT(D26,3))&"-"&TEXT(23,"000"))
A27: 24 | C27: =IF(E27="","",UPPER(LEFT(D27,3))&"-"&TEXT(24,"000"))
A28: 25 | C28: =IF(E28="","",UPPER(LEFT(D28,3))&"-"&TEXT(25,"000"))
A29: 26 | C29: =IF(E29="","",UPPER(LEFT(D29,3))&"-"&TEXT(26,"000"))
A30: 27 | C30: =IF(E30="","",UPPER(LEFT(D30,3))&"-"&TEXT(27,"000"))
A31: 28 | C31: =IF(E31="","",UPPER(LEFT(D31,3))&"-"&TEXT(28,"000"))
A32: 29 | C32: =IF(E32="","",UPPER(LEFT(D32,3))&"-"&TEXT(29,"000"))
A33: 30 | C33: =IF(E33="","",UPPER(LEFT(D33,3))&"-"&TEXT(30,"000"))
A34: 31 | C34: =IF(E34="","",UPPER(LEFT(D34,3))&"-"&TEXT(31,"000"))
A35: 32 | C35: =IF(E35="","",UPPER(LEFT(D35,3))&"-"&TEXT(32,"000"))
A36: 33 | C36: =IF(E36="","",UPPER(LEFT(D36,3))&"-"&TEXT(33,"000"))
A37: 34 | C37: =IF(E37="","",UPPER(LEFT(D37,3))&"-"&TEXT(34,"000"))
A38: 35 | C38: =IF(E38="","",UPPER(LEFT(D38,3))&"-"&TEXT(35,"000"))
A39: 36 | C39: =IF(E39="","",UPPER(LEFT(D39,3))&"-"&TEXT(36,"000"))
A40: 37 | C40: =IF(E40="","",UPPER(LEFT(D40,3))&"-"&TEXT(37,"000"))
...

Sheet 📧 Email Sequences
A1: SolidPro — Email Sequences Tracker
A2: Link each row to a Campaign ID from the Campaign Master sheet | * = Mandatory
A3: S.No | B3: Campaign ID * | C3: Asset ID | D3: Vertical * | E3: Asset Name / Title * | F3: Sequence Name | G3: Trigger / Entry Point | H3: Email # in Sequence | I3: Email Subject Line | J3: Email Type | K3: Audience Segment | L3: Linked Campaign ID | M3: Linked Lead Magnet ID | N3: CTA in Email | O3: CTA URL | P3: Send Day / Delay | Q3: ESP / Tool | R3: Template Used | S3: Open Rate Target | T3: Click Rate Target | U3: Owner * | V3: Support | W3: Requested By | X3: Brief Date | Y3: Due Date * | Z3: Pub / Post Date * | AA3: Priority | AB3: Status | AC3: Approved by Project Head | AD3: Approved by Manager | AE3: Final File / URL Link | AF3: Revision # | AG3: Feedback / Notes | AH3: Archived?
A4: 1 | C4: =IF(E4="","",UPPER(LEFT(D4,3))&"-"&TEXT(1,"000"))
A5: 2 | C5: =IF(E5="","",UPPER(LEFT(D5,3))&"-"&TEXT(2,"000"))
A6: 3 | C6: =IF(E6="","",UPPER(LEFT(D6,3))&"-"&TEXT(3,"000"))
A7: 4 | C7: =IF(E7="","",UPPER(LEFT(D7,3))&"-"&TEXT(4,"000"))
A8: 5 | C8: =IF(E8="","",UPPER(LEFT(D8,3))&"-"&TEXT(5,"000"))
A9: 6 | C9: =IF(E9="","",UPPER(LEFT(D9,3))&"-"&TEXT(6,"000"))
A10: 7 | C10: =IF(E10="","",UPPER(LEFT(D10,3))&"-"&TEXT(7,"000"))
A11: 8 | C11: =IF(E11="","",UPPER(LEFT(D11,3))&"-"&TEXT(8,"000"))
A12: 9 | C12: =IF(E12="","",UPPER(LEFT(D12,3))&"-"&TEXT(9,"000"))
A13: 10 | C13: =IF(E13="","",UPPER(LEFT(D13,3))&"-"&TEXT(10,"000"))
A14: 11 | C14: =IF(E14="","",UPPER(LEFT(D14,3))&"-"&TEXT(11,"000"))
A15: 12 | C15: =IF(E15="","",UPPER(LEFT(D15,3))&"-"&TEXT(12,"000"))
A16: 13 | C16: =IF(E16="","",UPPER(LEFT(D16,3))&"-"&TEXT(13,"000"))
A17: 14 | C17: =IF(E17="","",UPPER(LEFT(D17,3))&"-"&TEXT(14,"000"))
A18: 15 | C18: =IF(E18="","",UPPER(LEFT(D18,3))&"-"&TEXT(15,"000"))
A19: 16 | C19: =IF(E19="","",UPPER(LEFT(D19,3))&"-"&TEXT(16,"000"))
A20: 17 | C20: =IF(E20="","",UPPER(LEFT(D20,3))&"-"&TEXT(17,"000"))
A21: 18 | C21: =IF(E21="","",UPPER(LEFT(D21,3))&"-"&TEXT(18,"000"))
A22: 19 | C22: =IF(E22="","",UPPER(LEFT(D22,3))&"-"&TEXT(19,"000"))
A23: 20 | C23: =IF(E23="","",UPPER(LEFT(D23,3))&"-"&TEXT(20,"000"))
A24: 21 | C24: =IF(E24="","",UPPER(LEFT(D24,3))&"-"&TEXT(21,"000"))
A25: 22 | C25: =IF(E25="","",UPPER(LEFT(D25,3))&"-"&TEXT(22,"000"))
A26: 23 | C26: =IF(E26="","",UPPER(LEFT(D26,3))&"-"&TEXT(23,"000"))
A27: 24 | C27: =IF(E27="","",UPPER(LEFT(D27,3))&"-"&TEXT(24,"000"))
A28: 25 | C28: =IF(E28="","",UPPER(LEFT(D28,3))&"-"&TEXT(25,"000"))
A29: 26 | C29: =IF(E29="","",UPPER(LEFT(D29,3))&"-"&TEXT(26,"000"))
A30: 27 | C30: =IF(E30="","",UPPER(LEFT(D30,3))&"-"&TEXT(27,"000"))
A31: 28 | C31: =IF(E31="","",UPPER(LEFT(D31,3))&"-"&TEXT(28,"000"))
A32: 29 | C32: =IF(E32="","",UPPER(LEFT(D32,3))&"-"&TEXT(29,"000"))
A33: 30 | C33: =IF(E33="","",UPPER(LEFT(D33,3))&"-"&TEXT(30,"000"))
A34: 31 | C34: =IF(E34="","",UPPER(LEFT(D34,3))&"-"&TEXT(31,"000"))
A35: 32 | C35: =IF(E35="","",UPPER(LEFT(D35,3))&"-"&TEXT(32,"000"))
A36: 33 | C36: =IF(E36="","",UPPER(LEFT(D36,3))&"-"&TEXT(33,"000"))
A37: 34 | C37: =IF(E37="","",UPPER(LEFT(D37,3))&"-"&TEXT(34,"000"))
A38: 35 | C38: =IF(E38="","",UPPER(LEFT(D38,3))&"-"&TEXT(35,"000"))
A39: 36 | C39: =IF(E39="","",UPPER(LEFT(D39,3))&"-"&TEXT(36,"000"))
A40: 37 | C40: =IF(E40="","",UPPER(LEFT(D40,3))&"-"&TEXT(37,"000"))
...

Sheet 📣 Ad Copy
A1: SolidPro — Ad Copy Tracker
A2: Link each row to a Campaign ID from the Campaign Master sheet | * = Mandatory
A3: S.No | B3: Campaign ID * | C3: Asset ID | D3: Vertical * | E3: Asset Name / Title * | F3: Ad Platform | G3: Ad Format | H3: Ad Objective | I3: Headline (H1) | J3: Headline (H2) | K3: Body Copy | L3: CTA Text | M3: Destination URL | N3: Linked Creative ID | O3: Audience Targeting | P3: Budget (₹) | Q3: Run Start Date | R3: Run End Date | S3: UTM Parameters | T3: Ad Account / Campaign ID | U3: Owner * | V3: Support | W3: Requested By | X3: Brief Date | Y3: Due Date * | Z3: Pub / Post Date * | AA3: Priority | AB3: Status | AC3: Approved by Project Head | AD3: Approved by Manager | AE3: Final File / URL Link | AF3: Revision # | AG3: Feedback / Notes | AH3: Archived?
A4: 1 | C4: =IF(E4="","",UPPER(LEFT(D4,3))&"-"&TEXT(1,"000"))
A5: 2 | C5: =IF(E5="","",UPPER(LEFT(D5,3))&"-"&TEXT(2,"000"))
A6: 3 | C6: =IF(E6="","",UPPER(LEFT(D6,3))&"-"&TEXT(3,"000"))
A7: 4 | C7: =IF(E7="","",UPPER(LEFT(D7,3))&"-"&TEXT(4,"000"))
A8: 5 | C8: =IF(E8="","",UPPER(LEFT(D8,3))&"-"&TEXT(5,"000"))
A9: 6 | C9: =IF(E9="","",UPPER(LEFT(D9,3))&"-"&TEXT(6,"000"))
A10: 7 | C10: =IF(E10="","",UPPER(LEFT(D10,3))&"-"&TEXT(7,"000"))
A11: 8 | C11: =IF(E11="","",UPPER(LEFT(D11,3))&"-"&TEXT(8,"000"))
A12: 9 | C12: =IF(E12="","",UPPER(LEFT(D12,3))&"-"&TEXT(9,"000"))
A13: 10 | C13: =IF(E13="","",UPPER(LEFT(D13,3))&"-"&TEXT(10,"000"))
A14: 11 | C14: =IF(E14="","",UPPER(LEFT(D14,3))&"-"&TEXT(11,"000"))
A15: 12 | C15: =IF(E15="","",UPPER(LEFT(D15,3))&"-"&TEXT(12,"000"))
A16: 13 | C16: =IF(E16="","",UPPER(LEFT(D16,3))&"-"&TEXT(13,"000"))
A17: 14 | C17: =IF(E17="","",UPPER(LEFT(D17,3))&"-"&TEXT(14,"000"))
A18: 15 | C18: =IF(E18="","",UPPER(LEFT(D18,3))&"-"&TEXT(15,"000"))
A19: 16 | C19: =IF(E19="","",UPPER(LEFT(D19,3))&"-"&TEXT(16,"000"))
A20: 17 | C20: =IF(E20="","",UPPER(LEFT(D20,3))&"-"&TEXT(17,"000"))
A21: 18 | C21: =IF(E21="","",UPPER(LEFT(D21,3))&"-"&TEXT(18,"000"))
A22: 19 | C22: =IF(E22="","",UPPER(LEFT(D22,3))&"-"&TEXT(19,"000"))
A23: 20 | C23: =IF(E23="","",UPPER(LEFT(D23,3))&"-"&TEXT(20,"000"))
A24: 21 | C24: =IF(E24="","",UPPER(LEFT(D24,3))&"-"&TEXT(21,"000"))
A25: 22 | C25: =IF(E25="","",UPPER(LEFT(D25,3))&"-"&TEXT(22,"000"))
A26: 23 | C26: =IF(E26="","",UPPER(LEFT(D26,3))&"-"&TEXT(23,"000"))
A27: 24 | C27: =IF(E27="","",UPPER(LEFT(D27,3))&"-"&TEXT(24,"000"))
A28: 25 | C28: =IF(E28="","",UPPER(LEFT(D28,3))&"-"&TEXT(25,"000"))
A29: 26 | C29: =IF(E29="","",UPPER(LEFT(D29,3))&"-"&TEXT(26,"000"))
A30: 27 | C30: =IF(E30="","",UPPER(LEFT(D30,3))&"-"&TEXT(27,"000"))
A31: 28 | C31: =IF(E31="","",UPPER(LEFT(D31,3))&"-"&TEXT(28,"000"))
A32: 29 | C32: =IF(E32="","",UPPER(LEFT(D32,3))&"-"&TEXT(29,"000"))
A33: 30 | C33: =IF(E33="","",UPPER(LEFT(D33,3))&"-"&TEXT(30,"000"))
A34: 31 | C34: =IF(E34="","",UPPER(LEFT(D34,3))&"-"&TEXT(31,"000"))
A35: 32 | C35: =IF(E35="","",UPPER(LEFT(D35,3))&"-"&TEXT(32,"000"))
A36: 33 | C36: =IF(E36="","",UPPER(LEFT(D36,3))&"-"&TEXT(33,"000"))
A37: 34 | C37: =IF(E37="","",UPPER(LEFT(D37,3))&"-"&TEXT(34,"000"))
A38: 35 | C38: =IF(E38="","",UPPER(LEFT(D38,3))&"-"&TEXT(35,"000"))
A39: 36 | C39: =IF(E39="","",UPPER(LEFT(D39,3))&"-"&TEXT(36,"000"))
A40: 37 | C40: =IF(E40="","",UPPER(LEFT(D40,3))&"-"&TEXT(37,"000"))
...

Sheet 🔍 SEO
A1: SolidPro — SEO Tracker
A2: Link each row to a Campaign ID from the Campaign Master sheet | * = Mandatory
A3: S.No | B3: Campaign ID * | C3: Asset ID | D3: Vertical * | E3: Asset Name / Title * | F3: SEO Task Type | G3: Target Page / URL | H3: Primary Keyword | I3: Secondary Keywords | J3: Current Ranking | K3: Target Ranking | L3: Monthly Search Volume | M3: Keyword Difficulty | N3: On-Page Changes | O3: Backlink Target | P3: Linked Content ID | Q3: Linked LP ID | R3: Tool Used | S3: Tracking Implemented? | T3: Owner * | U3: Support | V3: Requested By | W3: Brief Date | X3: Due Date * | Y3: Pub / Post Date * | Z3: Priority | AA3: Status | AB3: Approved by Project Head | AC3: Approved by Manager | AD3: Final File / URL Link | AE3: Revision # | AF3: Feedback / Notes | AG3: Archived?
A4: 1 | C4: =IF(E4="","",UPPER(LEFT(D4,3))&"-"&TEXT(1,"000"))
A5: 2 | C5: =IF(E5="","",UPPER(LEFT(D5,3))&"-"&TEXT(2,"000"))
A6: 3 | C6: =IF(E6="","",UPPER(LEFT(D6,3))&"-"&TEXT(3,"000"))
A7: 4 | C7: =IF(E7="","",UPPER(LEFT(D7,3))&"-"&TEXT(4,"000"))
A8: 5 | C8: =IF(E8="","",UPPER(LEFT(D8,3))&"-"&TEXT(5,"000"))
A9: 6 | C9: =IF(E9="","",UPPER(LEFT(D9,3))&"-"&TEXT(6,"000"))
A10: 7 | C10: =IF(E10="","",UPPER(LEFT(D10,3))&"-"&TEXT(7,"000"))
A11: 8 | C11: =IF(E11="","",UPPER(LEFT(D11,3))&"-"&TEXT(8,"000"))
A12: 9 | C12: =IF(E12="","",UPPER(LEFT(D12,3))&"-"&TEXT(9,"000"))
A13: 10 | C13: =IF(E13="","",UPPER(LEFT(D13,3))&"-"&TEXT(10,"000"))
A14: 11 | C14: =IF(E14="","",UPPER(LEFT(D14,3))&"-"&TEXT(11,"000"))
A15: 12 | C15: =IF(E15="","",UPPER(LEFT(D15,3))&"-"&TEXT(12,"000"))
A16: 13 | C16: =IF(E16="","",UPPER(LEFT(D16,3))&"-"&TEXT(13,"000"))
A17: 14 | C17: =IF(E17="","",UPPER(LEFT(D17,3))&"-"&TEXT(14,"000"))
A18: 15 | C18: =IF(E18="","",UPPER(LEFT(D18,3))&"-"&TEXT(15,"000"))
A19: 16 | C19: =IF(E19="","",UPPER(LEFT(D19,3))&"-"&TEXT(16,"000"))
A20: 17 | C20: =IF(E20="","",UPPER(LEFT(D20,3))&"-"&TEXT(17,"000"))
A21: 18 | C21: =IF(E21="","",UPPER(LEFT(D21,3))&"-"&TEXT(18,"000"))
A22: 19 | C22: =IF(E22="","",UPPER(LEFT(D22,3))&"-"&TEXT(19,"000"))
A23: 20 | C23: =IF(E23="","",UPPER(LEFT(D23,3))&"-"&TEXT(20,"000"))
A24: 21 | C24: =IF(E24="","",UPPER(LEFT(D24,3))&"-"&TEXT(21,"000"))
A25: 22 | C25: =IF(E25="","",UPPER(LEFT(D25,3))&"-"&TEXT(22,"000"))
A26: 23 | C26: =IF(E26="","",UPPER(LEFT(D26,3))&"-"&TEXT(23,"000"))
A27: 24 | C27: =IF(E27="","",UPPER(LEFT(D27,3))&"-"&TEXT(24,"000"))
A28: 25 | C28: =IF(E28="","",UPPER(LEFT(D28,3))&"-"&TEXT(25,"000"))
A29: 26 | C29: =IF(E29="","",UPPER(LEFT(D29,3))&"-"&TEXT(26,"000"))
A30: 27 | C30: =IF(E30="","",UPPER(LEFT(D30,3))&"-"&TEXT(27,"000"))
A31: 28 | C31: =IF(E31="","",UPPER(LEFT(D31,3))&"-"&TEXT(28,"000"))
A32: 29 | C32: =IF(E32="","",UPPER(LEFT(D32,3))&"-"&TEXT(29,"000"))
A33: 30 | C33: =IF(E33="","",UPPER(LEFT(D33,3))&"-"&TEXT(30,"000"))
A34: 31 | C34: =IF(E34="","",UPPER(LEFT(D34,3))&"-"&TEXT(31,"000"))
A35: 32 | C35: =IF(E35="","",UPPER(LEFT(D35,3))&"-"&TEXT(32,"000"))
A36: 33 | C36: =IF(E36="","",UPPER(LEFT(D36,3))&"-"&TEXT(33,"000"))
A37: 34 | C37: =IF(E37="","",UPPER(LEFT(D37,3))&"-"&TEXT(34,"000"))
A38: 35 | C38: =IF(E38="","",UPPER(LEFT(D38,3))&"-"&TEXT(35,"000"))
A39: 36 | C39: =IF(E39="","",UPPER(LEFT(D39,3))&"-"&TEXT(36,"000"))
A40: 37 | C40: =IF(E40="","",UPPER(LEFT(D40,3))&"-"&TEXT(37,"000"))
...

Sheet 🎤 Webinars & Events
A1: SolidPro — Webinars & Events Tracker
A2: Link each row to a Campaign ID from the Campaign Master sheet | * = Mandatory
A3: S.No | B3: Campaign ID * | C3: Asset ID | D3: Vertical * | E3: Asset Name / Title * | F3: Event Type | G3: Event Title | H3: Event Format | I3: Topic / Agenda | J3: Speaker(s) | K3: Target Audience | L3: Registration Link | M3: Platform / Tool | N3: Event Date * | O3: Event Time | P3: Duration (mins) | Q3: Expected Attendees | R3: Actual Attendees | S3: Recording Link | T3: Follow-Up Email Sent? | U3: Lead Magnet Used | V3: Promotion Assets | W3: Owner * | X3: Support | Y3: Requested By | Z3: Brief Date | AA3: Due Date * | AB3: Pub / Post Date * | AC3: Priority | AD3: Status | AE3: Approved by Project Head | AF3: Approved by Manager | AG3: Final File / URL Link | AH3: Revision # | AI3: Feedback / Notes | AJ3: Archived?
A4: 1 | C4: =IF(E4="","",UPPER(LEFT(D4,3))&"-"&TEXT(1,"000"))
A5: 2 | C5: =IF(E5="","",UPPER(LEFT(D5,3))&"-"&TEXT(2,"000"))
A6: 3 | C6: =IF(E6="","",UPPER(LEFT(D6,3))&"-"&TEXT(3,"000"))
A7: 4 | C7: =IF(E7="","",UPPER(LEFT(D7,3))&"-"&TEXT(4,"000"))
A8: 5 | C8: =IF(E8="","",UPPER(LEFT(D8,3))&"-"&TEXT(5,"000"))
A9: 6 | C9: =IF(E9="","",UPPER(LEFT(D9,3))&"-"&TEXT(6,"000"))
A10: 7 | C10: =IF(E10="","",UPPER(LEFT(D10,3))&"-"&TEXT(7,"000"))
A11: 8 | C11: =IF(E11="","",UPPER(LEFT(D11,3))&"-"&TEXT(8,"000"))
A12: 9 | C12: =IF(E12="","",UPPER(LEFT(D12,3))&"-"&TEXT(9,"000"))
A13: 10 | C13: =IF(E13="","",UPPER(LEFT(D13,3))&"-"&TEXT(10,"000"))
A14: 11 | C14: =IF(E14="","",UPPER(LEFT(D14,3))&"-"&TEXT(11,"000"))
A15: 12 | C15: =IF(E15="","",UPPER(LEFT(D15,3))&"-"&TEXT(12,"000"))
A16: 13 | C16: =IF(E16="","",UPPER(LEFT(D16,3))&"-"&TEXT(13,"000"))
A17: 14 | C17: =IF(E17="","",UPPER(LEFT(D17,3))&"-"&TEXT(14,"000"))
A18: 15 | C18: =IF(E18="","",UPPER(LEFT(D18,3))&"-"&TEXT(15,"000"))
A19: 16 | C19: =IF(E19="","",UPPER(LEFT(D19,3))&"-"&TEXT(16,"000"))
A20: 17 | C20: =IF(E20="","",UPPER(LEFT(D20,3))&"-"&TEXT(17,"000"))
A21: 18 | C21: =IF(E21="","",UPPER(LEFT(D21,3))&"-"&TEXT(18,"000"))
A22: 19 | C22: =IF(E22="","",UPPER(LEFT(D22,3))&"-"&TEXT(19,"000"))
A23: 20 | C23: =IF(E23="","",UPPER(LEFT(D23,3))&"-"&TEXT(20,"000"))
A24: 21 | C24: =IF(E24="","",UPPER(LEFT(D24,3))&"-"&TEXT(21,"000"))
A25: 22 | C25: =IF(E25="","",UPPER(LEFT(D25,3))&"-"&TEXT(22,"000"))
A26: 23 | C26: =IF(E26="","",UPPER(LEFT(D26,3))&"-"&TEXT(23,"000"))
A27: 24 | C27: =IF(E27="","",UPPER(LEFT(D27,3))&"-"&TEXT(24,"000"))
A28: 25 | C28: =IF(E28="","",UPPER(LEFT(D28,3))&"-"&TEXT(25,"000"))
A29: 26 | C29: =IF(E29="","",UPPER(LEFT(D29,3))&"-"&TEXT(26,"000"))
A30: 27 | C30: =IF(E30="","",UPPER(LEFT(D30,3))&"-"&TEXT(27,"000"))
A31: 28 | C31: =IF(E31="","",UPPER(LEFT(D31,3))&"-"&TEXT(28,"000"))
A32: 29 | C32: =IF(E32="","",UPPER(LEFT(D32,3))&"-"&TEXT(29,"000"))
A33: 30 | C33: =IF(E33="","",UPPER(LEFT(D33,3))&"-"&TEXT(30,"000"))
A34: 31 | C34: =IF(E34="","",UPPER(LEFT(D34,3))&"-"&TEXT(31,"000"))
A35: 32 | C35: =IF(E35="","",UPPER(LEFT(D35,3))&"-"&TEXT(32,"000"))
A36: 33 | C36: =IF(E36="","",UPPER(LEFT(D36,3))&"-"&TEXT(33,"000"))
A37: 34 | C37: =IF(E37="","",UPPER(LEFT(D37,3))&"-"&TEXT(34,"000"))
A38: 35 | C38: =IF(E38="","",UPPER(LEFT(D38,3))&"-"&TEXT(35,"000"))
A39: 36 | C39: =IF(E39="","",UPPER(LEFT(D39,3))&"-"&TEXT(36,"000"))
A40: 37 | C40: =IF(E40="","",UPPER(LEFT(D40,3))&"-"&TEXT(37,"000"))
...

Sheet 📊 Dashboard
A1: SolidPro Marketing — Campaign Dashboard
A2: Auto-calculated from all tracker sheets | Refresh by pressing Ctrl+Alt+F9
A4: Assets by Tracker Sheet
A5: 🎨 Creatives | B5: =COUNTA('🎨 Creatives'!E4:E53)
A6: 🌐 Landing Pages | B6: =COUNTA('🌐 Landing Pages'!E4:E53)
A7: ✍ Content Writing | B7: =COUNTA('✍ Content Writing'!E4:E53)
A8: 🎁 Lead Magnets | B8: =COUNTA('🎁 Lead Magnets'!E4:E53)
A9: 📧 Email Sequences | B9: =COUNTA('📧 Email Sequences'!E4:E53)
A10: 📣 Ad Copy | B10: =COUNTA('📣 Ad Copy'!E4:E53)
A11: 🔍 SEO | B11: =COUNTA('🔍 SEO'!E4:E53)
A12: 🎤 Webinars & Events | B12: =COUNTA('🎤 Webinars & Events'!E4:E53)
A13: TOTAL ASSETS | B13: =SUM(B5:B12)
A16: Campaigns by Status
A17: 🗓 Planning | B17: =COUNTIF('🗂 Campaign Master'!N4:N53,"*Planning*")
A18: 🚀 Active | B18: =COUNTIF('🗂 Campaign Master'!N4:N53,"*Active*")
A19: ✅ Completed | B19: =COUNTIF('🗂 Campaign Master'!N4:N53,"*Completed*")
A20: ⏸ Paused | B20: =COUNTIF('🗂 Campaign Master'!N4:N53,"*Paused*")
A21: ❌ Cancelled | B21: =COUNTIF('🗂 Campaign Master'!N4:N53,"*Cancelled*")
A25: Assets by Vertical
A26: Digital Transformation | B26: =COUNTIF('🗂 Campaign Master'!D4:D53,"*Digital Transformation*")
A27: Industrial Goods & Consumer Products | B27: =COUNTIF('🗂 Campaign Master'!D4:D53,"*Industrial Goods & Consumer Products*")
A28: Structural Engineering | B28: =COUNTIF('🗂 Campaign Master'!D4:D53,"*Structural Engineering*")
A29: MedTech | B29: =COUNTIF('🗂 Campaign Master'!D4:D53,"*MedTech*")
A30: Energy & Utilities | B30: =COUNTIF('🗂 Campaign Master'!D4:D53,"*Energy & Utilities*")
A31: Sustainability | B31: =COUNTIF('🗂 Campaign Master'!D4:D53,"*Sustainability*")
A32: BFSI | B32: =COUNTIF('🗂 Campaign Master'!D4:D53,"*BFSI*")
A33: Product Innovation | B33: =COUNTIF('🗂 Campaign Master'!D4:D53,"*Product Innovation*")
A34: SolidPro AI | B34: =COUNTIF('🗂 Campaign Master'!D4:D53,"*SolidPro AI*")
A35: Other | B35: =COUNTIF('🗂 Campaign Master'!D4:D53,"*Other*")

Sheet 📖 How To Use
A1: SolidPro Marketing Tracker — How To Use This File
A3: STEP 1 — Create a Campaign
A4: Go to 🗂 Campaign Master. Fill in Campaign Name, Vertical, Goal, Dates, Owner, and Status. The Campaign ID (e.g. CAMP-001) is auto-generated. This ID is your anchor — every asset in every other tab must reference it.
A6: STEP 2 — Add Creatives (Graphic / Video)
A7: Go to 🎨 Creatives. Paste the Campaign ID in column B. Fill in asset details — Content Type, Asset Type, Owner, Due Date, Post Date, and Status. Asset IDs are auto-generated.
A9: STEP 3 — Plan Landing Pages
A10: Go to 🌐 Landing Pages. Link to the Campaign ID. Fill in Page Goal, Type, CTA, Form Fields, SEO Title, and Dev Owner (SS). Paste linked Creative Asset IDs and Lead Magnet IDs once created.
A12: STEP 4 — Brief Content Writing
A13: Go to ✍ Content Writing. Link to Campaign ID. Specify format, topic, target keyword, word count, and funnel stage. Paste the Landing Page ID if content supports a landing page.
A15: STEP 5 — Add Lead Magnets
A16: Go to 🎁 Lead Magnets. Link to Campaign ID. Choose type (Assessment, Downloadable PDF, Checklist, etc.), specify if gated, and note where leads are routed (HubSpot, Zoho, etc.).
A18: STEP 6 — Plan Email Sequences
... A34: Example flow: Campaign CAMP-001 (LinkedIn Lead Gen) → Social Post (CRE-001) drives traffic → Landing Page (LP-001) captures leads → Lead Magnet PDF (LM-001) is the offer → Email Sequence (EM-001) nurtures the lead. All rows in each sheet carry CAMP-001 in Column B.
