Workbook

Sheet 🌐 Landing Pages
A1: SolidPro — Landing Pages Tracker | FILE 2 of 2
A2: Asset ID format: CAMPID-LP-001 | Always link Creative ID + Lead Magnet ID before publishing | * = Mandatory
A3: S.No | B3: Campaign ID * | C3: Asset ID | D3: Vertical * | E3: Page Name / Title * | F3: Landing Page Type | G3: Page Goal | H3: Page URL / Slug | I3: CTA Text | J3: Form Fields Required | K3: SEO Title | L3: Meta Description | M3: Linked Creative ID | N3: Linked Lead Magnet ID | O3: Linked Email Seq ID | P3: Dev Owner (SS) * | Q3: Content Writer | R3: Brief Date | S3: Due Date * | T3: Pub / Go-Live Date * | U3: Priority | V3: Status | W3: Approved by Project Head | X3: Approved by Manager | Y3: A/B Test? | Z3: UTM Parameters | AA3: Conversion Goal | AB3: Final URL | AC3: Feedback / Notes | AD3: Archived?
A4: 1 | C4: =IF(B4="","",B4&"-LP-"&TEXT(1,"000"))
A5: 2 | C5: =IF(B5="","",B5&"-LP-"&TEXT(2,"000"))
A6: 3 | C6: =IF(B6="","",B6&"-LP-"&TEXT(3,"000"))
A7: 4 | C7: =IF(B7="","",B7&"-LP-"&TEXT(4,"000"))
A8: 5 | C8: =IF(B8="","",B8&"-LP-"&TEXT(5,"000"))
A9: 6 | C9: =IF(B9="","",B9&"-LP-"&TEXT(6,"000"))
A10: 7 | C10: =IF(B10="","",B10&"-LP-"&TEXT(7,"000"))
A11: 8 | C11: =IF(B11="","",B11&"-LP-"&TEXT(8,"000"))
A12: 9 | C12: =IF(B12="","",B12&"-LP-"&TEXT(9,"000"))
A13: 10 | C13: =IF(B13="","",B13&"-LP-"&TEXT(10,"000"))
A14: 11 | C14: =IF(B14="","",B14&"-LP-"&TEXT(11,"000"))
A15: 12 | C15: =IF(B15="","",B15&"-LP-"&TEXT(12,"000"))
A16: 13 | C16: =IF(B16="","",B16&"-LP-"&TEXT(13,"000"))
A17: 14 | C17: =IF(B17="","",B17&"-LP-"&TEXT(14,"000"))
A18: 15 | C18: =IF(B18="","",B18&"-LP-"&TEXT(15,"000"))
A19: 16 | C19: =IF(B19="","",B19&"-LP-"&TEXT(16,"000"))
A20: 17 | C20: =IF(B20="","",B20&"-LP-"&TEXT(17,"000"))
A21: 18 | C21: =IF(B21="","",B21&"-LP-"&TEXT(18,"000"))
A22: 19 | C22: =IF(B22="","",B22&"-LP-"&TEXT(19,"000"))
A23: 20 | C23: =IF(B23="","",B23&"-LP-"&TEXT(20,"000"))
A24: 21 | C24: =IF(B24="","",B24&"-LP-"&TEXT(21,"000"))
A25: 22 | C25: =IF(B25="","",B25&"-LP-"&TEXT(22,"000"))
A26: 23 | C26: =IF(B26="","",B26&"-LP-"&TEXT(23,"000"))
A27: 24 | C27: =IF(B27="","",B27&"-LP-"&TEXT(24,"000"))
A28: 25 | C28: =IF(B28="","",B28&"-LP-"&TEXT(25,"000"))
A29: 26 | C29: =IF(B29="","",B29&"-LP-"&TEXT(26,"000"))
A30: 27 | C30: =IF(B30="","",B30&"-LP-"&TEXT(27,"000"))
A31: 28 | C31: =IF(B31="","",B31&"-LP-"&TEXT(28,"000"))
A32: 29 | C32: =IF(B32="","",B32&"-LP-"&TEXT(29,"000"))
A33: 30 | C33: =IF(B33="","",B33&"-LP-"&TEXT(30,"000"))
A34: 31 | C34: =IF(B34="","",B34&"-LP-"&TEXT(31,"000"))
A35: 32 | C35: =IF(B35="","",B35&"-LP-"&TEXT(32,"000"))
A36: 33 | C36: =IF(B36="","",B36&"-LP-"&TEXT(33,"000"))
A37: 34 | C37: =IF(B37="","",B37&"-LP-"&TEXT(34,"000"))
A38: 35 | C38: =IF(B38="","",B38&"-LP-"&TEXT(35,"000"))
A39: 36 | C39: =IF(B39="","",B39&"-LP-"&TEXT(36,"000"))
A40: 37 | C40: =IF(B40="","",B40&"-LP-"&TEXT(37,"000"))
...

Sheet ✍ Content Writing
A1: SolidPro — Content Writing Tracker | FILE 2 of 2
A2: Asset ID format: CAMPID-CW-001 | One row per content piece | Link to Landing Page + Lead Magnet IDs | * = Mandatory
A3: S.No | B3: Campaign ID * | C3: Asset ID | D3: Vertical * | E3: Content Title * | F3: Content Format | G3: Topic / Angle | H3: Target Keyword(s) | I3: Word Count (Target) | J3: Audience Persona | K3: Funnel Stage | L3: Tone of Voice | M3: Linked LP ID | N3: Linked Lead Magnet ID | O3: References / Resources | P3: Content Writer * | Q3: Reviewer | R3: Brief Date | S3: Due Date * | T3: Pub / Go-Live Date * | U3: Draft Link | V3: Priority | W3: Status | X3: Approved by Project Head | Y3: Approved by Manager | Z3: SEO Optimised? | AA3: CMS Published? | AB3: Feedback / Notes | AC3: Archived?
A4: 1 | C4: =IF(B4="","",B4&"-CW-"&TEXT(1,"000"))
A5: 2 | C5: =IF(B5="","",B5&"-CW-"&TEXT(2,"000"))
A6: 3 | C6: =IF(B6="","",B6&"-CW-"&TEXT(3,"000"))
A7: 4 | C7: =IF(B7="","",B7&"-CW-"&TEXT(4,"000"))
A8: 5 | C8: =IF(B8="","",B8&"-CW-"&TEXT(5,"000"))
A9: 6 | C9: =IF(B9="","",B9&"-CW-"&TEXT(6,"000"))
A10: 7 | C10: =IF(B10="","",B10&"-CW-"&TEXT(7,"000"))
A11: 8 | C11: =IF(B11="","",B11&"-CW-"&TEXT(8,"000"))
A12: 9 | C12: =IF(B12="","",B12&"-CW-"&TEXT(9,"000"))
A13: 10 | C13: =IF(B13="","",B13&"-CW-"&TEXT(10,"000"))
A14: 11 | C14: =IF(B14="","",B14&"-CW-"&TEXT(11,"000"))
A15: 12 | C15: =IF(B15="","",B15&"-CW-"&TEXT(12,"000"))
A16: 13 | C16: =IF(B16="","",B16&"-CW-"&TEXT(13,"000"))
A17: 14 | C17: =IF(B17="","",B17&"-CW-"&TEXT(14,"000"))
A18: 15 | C18: =IF(B18="","",B18&"-CW-"&TEXT(15,"000"))
A19: 16 | C19: =IF(B19="","",B19&"-CW-"&TEXT(16,"000"))
A20: 17 | C20: =IF(B20="","",B20&"-CW-"&TEXT(17,"000"))
A21: 18 | C21: =IF(B21="","",B21&"-CW-"&TEXT(18,"000"))
A22: 19 | C22: =IF(B22="","",B22&"-CW-"&TEXT(19,"000"))
A23: 20 | C23: =IF(B23="","",B23&"-CW-"&TEXT(20,"000"))
A24: 21 | C24: =IF(B24="","",B24&"-CW-"&TEXT(21,"000"))
A25: 22 | C25: =IF(B25="","",B25&"-CW-"&TEXT(22,"000"))
A26: 23 | C26: =IF(B26="","",B26&"-CW-"&TEXT(23,"000"))
A27: 24 | C27: =IF(B27="","",B27&"-CW-"&TEXT(24,"000"))
A28: 25 | C28: =IF(B28="","",B28&"-CW-"&TEXT(25,"000"))
A29: 26 | C29: =IF(B29="","",B29&"-CW-"&TEXT(26,"000"))
A30: 27 | C30: =IF(B30="","",B30&"-CW-"&TEXT(27,"000"))
A31: 28 | C31: =IF(B31="","",B31&"-CW-"&TEXT(28,"000"))
A32: 29 | C32: =IF(B32="","",B32&"-CW-"&TEXT(29,"000"))
A33: 30 | C33: =IF(B33="","",B33&"-CW-"&TEXT(30,"000"))
A34: 31 | C34: =IF(B34="","",B34&"-CW-"&TEXT(31,"000"))
A35: 32 | C35: =IF(B35="","",B35&"-CW-"&TEXT(32,"000"))
A36: 33 | C36: =IF(B36="","",B36&"-CW-"&TEXT(33,"000"))
A37: 34 | C37: =IF(B37="","",B37&"-CW-"&TEXT(34,"000"))
A38: 35 | C38: =IF(B38="","",B38&"-CW-"&TEXT(35,"000"))
A39: 36 | C39: =IF(B39="","",B39&"-CW-"&TEXT(36,"000"))
A40: 37 | C40: =IF(B40="","",B40&"-CW-"&TEXT(37,"000"))
...

Sheet 🎁 Lead Magnets
A1: SolidPro — Lead Magnets Tracker | FILE 2 of 2
A2: Asset ID format: CAMPID-LM-001 | Assessments / PDFs / Calculators / Checklists | * = Mandatory
A3: S.No | B3: Campaign ID * | C3: Asset ID | D3: Vertical * | E3: Lead Magnet Name * | F3: Lead Magnet Type | G3: Topic / Theme | H3: Format / Delivery | I3: Target Persona | J3: Funnel Stage | K3: Linked LP ID | L3: Linked Content ID | M3: No. of Pages / Questions | N3: Content Writer | O3: Designer | P3: Gating? (Form Required?) | Q3: Form Fields | R3: Lead Data Goes To | S3: Download / Access Link | T3: Results / Score Defined? | U3: Brief Date | V3: Due Date * | W3: Pub / Go-Live Date * | X3: Owner * | Y3: Priority | Z3: Status | AA3: Approved by Project Head | AB3: Approved by Manager | AC3: Feedback / Notes | AD3: Archived?
A4: 1 | C4: =IF(B4="","",B4&"-LM-"&TEXT(1,"000"))
A5: 2 | C5: =IF(B5="","",B5&"-LM-"&TEXT(2,"000"))
A6: 3 | C6: =IF(B6="","",B6&"-LM-"&TEXT(3,"000"))
A7: 4 | C7: =IF(B7="","",B7&"-LM-"&TEXT(4,"000"))
A8: 5 | C8: =IF(B8="","",B8&"-LM-"&TEXT(5,"000"))
A9: 6 | C9: =IF(B9="","",B9&"-LM-"&TEXT(6,"000"))
A10: 7 | C10: =IF(B10="","",B10&"-LM-"&TEXT(7,"000"))
A11: 8 | C11: =IF(B11="","",B11&"-LM-"&TEXT(8,"000"))
A12: 9 | C12: =IF(B12="","",B12&"-LM-"&TEXT(9,"000"))
A13: 10 | C13: =IF(B13="","",B13&"-LM-"&TEXT(10,"000"))
A14: 11 | C14: =IF(B14="","",B14&"-LM-"&TEXT(11,"000"))
A15: 12 | C15: =IF(B15="","",B15&"-LM-"&TEXT(12,"000"))
A16: 13 | C16: =IF(B16="","",B16&"-LM-"&TEXT(13,"000"))
A17: 14 | C17: =IF(B17="","",B17&"-LM-"&TEXT(14,"000"))
A18: 15 | C18: =IF(B18="","",B18&"-LM-"&TEXT(15,"000"))
A19: 16 | C19: =IF(B19="","",B19&"-LM-"&TEXT(16,"000"))
A20: 17 | C20: =IF(B20="","",B20&"-LM-"&TEXT(17,"000"))
A21: 18 | C21: =IF(B21="","",B21&"-LM-"&TEXT(18,"000"))
A22: 19 | C22: =IF(B22="","",B22&"-LM-"&TEXT(19,"000"))
A23: 20 | C23: =IF(B23="","",B23&"-LM-"&TEXT(20,"000"))
A24: 21 | C24: =IF(B24="","",B24&"-LM-"&TEXT(21,"000"))
A25: 22 | C25: =IF(B25="","",B25&"-LM-"&TEXT(22,"000"))
A26: 23 | C26: =IF(B26="","",B26&"-LM-"&TEXT(23,"000"))
A27: 24 | C27: =IF(B27="","",B27&"-LM-"&TEXT(24,"000"))
A28: 25 | C28: =IF(B28="","",B28&"-LM-"&TEXT(25,"000"))
A29: 26 | C29: =IF(B29="","",B29&"-LM-"&TEXT(26,"000"))
A30: 27 | C30: =IF(B30="","",B30&"-LM-"&TEXT(27,"000"))
A31: 28 | C31: =IF(B31="","",B31&"-LM-"&TEXT(28,"000"))
A32: 29 | C32: =IF(B32="","",B32&"-LM-"&TEXT(29,"000"))
A33: 30 | C33: =IF(B33="","",B33&"-LM-"&TEXT(30,"000"))
A34: 31 | C34: =IF(B34="","",B34&"-LM-"&TEXT(31,"000"))
A35: 32 | C35: =IF(B35="","",B35&"-LM-"&TEXT(32,"000"))
A36: 33 | C36: =IF(B36="","",B36&"-LM-"&TEXT(33,"000"))
A37: 34 | C37: =IF(B37="","",B37&"-LM-"&TEXT(34,"000"))
A38: 35 | C38: =IF(B38="","",B38&"-LM-"&TEXT(35,"000"))
A39: 36 | C39: =IF(B39="","",B39&"-LM-"&TEXT(36,"000"))
A40: 37 | C40: =IF(B40="","",B40&"-LM-"&TEXT(37,"000"))
...

Sheet 📧 Email Sequences
A1: SolidPro — Email Sequences Tracker | FILE 2 of 2
A2: Asset ID format: CAMPID-EM-001 | Each email in a sequence = one row | * = Mandatory
A3: S.No | B3: Campaign ID * | C3: Asset ID | D3: Vertical * | E3: Sequence Name * | F3: Email # in Sequence | G3: Email Subject Line * | H3: Preview Text | I3: Email Type | J3: Trigger / Entry Point | K3: Audience Segment | L3: Send Day / Delay | M3: CTA in Email | N3: CTA URL | O3: Linked Lead Magnet ID | P3: Linked LP ID | Q3: ESP / Tool | R3: Template Used | S3: Open Rate Target (%) | T3: Click Rate Target (%) | U3: Content Writer * | V3: Brief Date | W3: Due Date * | X3: Pub / Go-Live Date * | Y3: Priority | Z3: Status | AA3: Approved by Project Head | AB3: Approved by Manager | AC3: Feedback / Notes | AD3: Archived?
A4: 1 | C4: =IF(B4="","",B4&"-EM-"&TEXT(1,"000"))
A5: 2 | C5: =IF(B5="","",B5&"-EM-"&TEXT(2,"000"))
A6: 3 | C6: =IF(B6="","",B6&"-EM-"&TEXT(3,"000"))
A7: 4 | C7: =IF(B7="","",B7&"-EM-"&TEXT(4,"000"))
A8: 5 | C8: =IF(B8="","",B8&"-EM-"&TEXT(5,"000"))
A9: 6 | C9: =IF(B9="","",B9&"-EM-"&TEXT(6,"000"))
A10: 7 | C10: =IF(B10="","",B10&"-EM-"&TEXT(7,"000"))
A11: 8 | C11: =IF(B11="","",B11&"-EM-"&TEXT(8,"000"))
A12: 9 | C12: =IF(B12="","",B12&"-EM-"&TEXT(9,"000"))
A13: 10 | C13: =IF(B13="","",B13&"-EM-"&TEXT(10,"000"))
A14: 11 | C14: =IF(B14="","",B14&"-EM-"&TEXT(11,"000"))
A15: 12 | C15: =IF(B15="","",B15&"-EM-"&TEXT(12,"000"))
A16: 13 | C16: =IF(B16="","",B16&"-EM-"&TEXT(13,"000"))
A17: 14 | C17: =IF(B17="","",B17&"-EM-"&TEXT(14,"000"))
A18: 15 | C18: =IF(B18="","",B18&"-EM-"&TEXT(15,"000"))
A19: 16 | C19: =IF(B19="","",B19&"-EM-"&TEXT(16,"000"))
A20: 17 | C20: =IF(B20="","",B20&"-EM-"&TEXT(17,"000"))
A21: 18 | C21: =IF(B21="","",B21&"-EM-"&TEXT(18,"000"))
A22: 19 | C22: =IF(B22="","",B22&"-EM-"&TEXT(19,"000"))
A23: 20 | C23: =IF(B23="","",B23&"-EM-"&TEXT(20,"000"))
A24: 21 | C24: =IF(B24="","",B24&"-EM-"&TEXT(21,"000"))
A25: 22 | C25: =IF(B25="","",B25&"-EM-"&TEXT(22,"000"))
A26: 23 | C26: =IF(B26="","",B26&"-EM-"&TEXT(23,"000"))
A27: 24 | C27: =IF(B27="","",B27&"-EM-"&TEXT(24,"000"))
A28: 25 | C28: =IF(B28="","",B28&"-EM-"&TEXT(25,"000"))
A29: 26 | C29: =IF(B29="","",B29&"-EM-"&TEXT(26,"000"))
A30: 27 | C30: =IF(B30="","",B30&"-EM-"&TEXT(27,"000"))
A31: 28 | C31: =IF(B31="","",B31&"-EM-"&TEXT(28,"000"))
A32: 29 | C32: =IF(B32="","",B32&"-EM-"&TEXT(29,"000"))
A33: 30 | C33: =IF(B33="","",B33&"-EM-"&TEXT(30,"000"))
A34: 31 | C34: =IF(B34="","",B34&"-EM-"&TEXT(31,"000"))
A35: 32 | C35: =IF(B35="","",B35&"-EM-"&TEXT(32,"000"))
A36: 33 | C36: =IF(B36="","",B36&"-EM-"&TEXT(33,"000"))
A37: 34 | C37: =IF(B37="","",B37&"-EM-"&TEXT(34,"000"))
A38: 35 | C38: =IF(B38="","",B38&"-EM-"&TEXT(35,"000"))
A39: 36 | C39: =IF(B39="","",B39&"-EM-"&TEXT(36,"000"))
A40: 37 | C40: =IF(B40="","",B40&"-EM-"&TEXT(37,"000"))
...

Sheet 🔍 SEO
A1: SolidPro — SEO Tracker | FILE 2 of 2
A2: Asset ID format: CAMPID-SEO-001 | One row per SEO task | * = Mandatory
A3: S.No | B3: Campaign ID * | C3: Asset ID | D3: Vertical * | E3: SEO Task Name * | F3: SEO Task Type | G3: Target Page / URL | H3: Primary Keyword | I3: Secondary Keywords | J3: Current Ranking | K3: Target Ranking | L3: Monthly Search Vol. | M3: Keyword Difficulty | N3: On-Page Changes | O3: Backlink Target | P3: Linked Content ID | Q3: Linked LP ID | R3: Tool Used | S3: Owner * | T3: Brief Date | U3: Due Date * | V3: Pub / Go-Live Date * | W3: Priority | X3: Status | Y3: Approved by Project Head | Z3: Approved by Manager | AA3: Tracking Implemented? | AB3: Feedback / Notes | AC3: Archived?
A4: 1 | C4: =IF(B4="","",B4&"-SEO-"&TEXT(1,"000"))
A5: 2 | C5: =IF(B5="","",B5&"-SEO-"&TEXT(2,"000"))
A6: 3 | C6: =IF(B6="","",B6&"-SEO-"&TEXT(3,"000"))
A7: 4 | C7: =IF(B7="","",B7&"-SEO-"&TEXT(4,"000"))
A8: 5 | C8: =IF(B8="","",B8&"-SEO-"&TEXT(5,"000"))
A9: 6 | C9: =IF(B9="","",B9&"-SEO-"&TEXT(6,"000"))
A10: 7 | C10: =IF(B10="","",B10&"-SEO-"&TEXT(7,"000"))
A11: 8 | C11: =IF(B11="","",B11&"-SEO-"&TEXT(8,"000"))
A12: 9 | C12: =IF(B12="","",B12&"-SEO-"&TEXT(9,"000"))
A13: 10 | C13: =IF(B13="","",B13&"-SEO-"&TEXT(10,"000"))
A14: 11 | C14: =IF(B14="","",B14&"-SEO-"&TEXT(11,"000"))
A15: 12 | C15: =IF(B15="","",B15&"-SEO-"&TEXT(12,"000"))
A16: 13 | C16: =IF(B16="","",B16&"-SEO-"&TEXT(13,"000"))
A17: 14 | C17: =IF(B17="","",B17&"-SEO-"&TEXT(14,"000"))
A18: 15 | C18: =IF(B18="","",B18&"-SEO-"&TEXT(15,"000"))
A19: 16 | C19: =IF(B19="","",B19&"-SEO-"&TEXT(16,"000"))
A20: 17 | C20: =IF(B20="","",B20&"-SEO-"&TEXT(17,"000"))
A21: 18 | C21: =IF(B21="","",B21&"-SEO-"&TEXT(18,"000"))
A22: 19 | C22: =IF(B22="","",B22&"-SEO-"&TEXT(19,"000"))
A23: 20 | C23: =IF(B23="","",B23&"-SEO-"&TEXT(20,"000"))
A24: 21 | C24: =IF(B24="","",B24&"-SEO-"&TEXT(21,"000"))
A25: 22 | C25: =IF(B25="","",B25&"-SEO-"&TEXT(22,"000"))
A26: 23 | C26: =IF(B26="","",B26&"-SEO-"&TEXT(23,"000"))
A27: 24 | C27: =IF(B27="","",B27&"-SEO-"&TEXT(24,"000"))
A28: 25 | C28: =IF(B28="","",B28&"-SEO-"&TEXT(25,"000"))
A29: 26 | C29: =IF(B29="","",B29&"-SEO-"&TEXT(26,"000"))
A30: 27 | C30: =IF(B30="","",B30&"-SEO-"&TEXT(27,"000"))
A31: 28 | C31: =IF(B31="","",B31&"-SEO-"&TEXT(28,"000"))
A32: 29 | C32: =IF(B32="","",B32&"-SEO-"&TEXT(29,"000"))
A33: 30 | C33: =IF(B33="","",B33&"-SEO-"&TEXT(30,"000"))
A34: 31 | C34: =IF(B34="","",B34&"-SEO-"&TEXT(31,"000"))
A35: 32 | C35: =IF(B35="","",B35&"-SEO-"&TEXT(32,"000"))
A36: 33 | C36: =IF(B36="","",B36&"-SEO-"&TEXT(33,"000"))
A37: 34 | C37: =IF(B37="","",B37&"-SEO-"&TEXT(34,"000"))
A38: 35 | C38: =IF(B38="","",B38&"-SEO-"&TEXT(35,"000"))
A39: 36 | C39: =IF(B39="","",B39&"-SEO-"&TEXT(36,"000"))
A40: 37 | C40: =IF(B40="","",B40&"-SEO-"&TEXT(37,"000"))
...

Sheet 🎤 Webinars & Events
A1: SolidPro — Webinars & Events Tracker | FILE 2 of 2
A2: Asset ID format: CAMPID-EV-001 | Link LP + Lead Magnet IDs before going live | * = Mandatory
A3: S.No | B3: Campaign ID * | C3: Asset ID | D3: Vertical * | E3: Event Name * | F3: Event Type | G3: Event Format | H3: Topic / Agenda | I3: Speaker(s) | J3: Target Audience | K3: Registration Link | L3: Platform / Tool | M3: Event Date * | N3: Event Time | O3: Duration (mins) | P3: Linked LP ID | Q3: Linked Lead Magnet ID | R3: Promotion Asset IDs | S3: Expected Attendees | T3: Actual Attendees | U3: Recording Link | V3: Follow-Up Email Sent? | W3: Owner * | X3: Brief Date | Y3: Due Date * | Z3: Pub / Go-Live Date * | AA3: Priority | AB3: Status | AC3: Approved by Project Head | AD3: Approved by Manager | AE3: Feedback / Notes | AF3: Archived?
A4: 1 | C4: =IF(B4="","",B4&"-EV-"&TEXT(1,"000"))
A5: 2 | C5: =IF(B5="","",B5&"-EV-"&TEXT(2,"000"))
A6: 3 | C6: =IF(B6="","",B6&"-EV-"&TEXT(3,"000"))
A7: 4 | C7: =IF(B7="","",B7&"-EV-"&TEXT(4,"000"))
A8: 5 | C8: =IF(B8="","",B8&"-EV-"&TEXT(5,"000"))
A9: 6 | C9: =IF(B9="","",B9&"-EV-"&TEXT(6,"000"))
A10: 7 | C10: =IF(B10="","",B10&"-EV-"&TEXT(7,"000"))
A11: 8 | C11: =IF(B11="","",B11&"-EV-"&TEXT(8,"000"))
A12: 9 | C12: =IF(B12="","",B12&"-EV-"&TEXT(9,"000"))
A13: 10 | C13: =IF(B13="","",B13&"-EV-"&TEXT(10,"000"))
A14: 11 | C14: =IF(B14="","",B14&"-EV-"&TEXT(11,"000"))
A15: 12 | C15: =IF(B15="","",B15&"-EV-"&TEXT(12,"000"))
A16: 13 | C16: =IF(B16="","",B16&"-EV-"&TEXT(13,"000"))
A17: 14 | C17: =IF(B17="","",B17&"-EV-"&TEXT(14,"000"))
A18: 15 | C18: =IF(B18="","",B18&"-EV-"&TEXT(15,"000"))
A19: 16 | C19: =IF(B19="","",B19&"-EV-"&TEXT(16,"000"))
A20: 17 | C20: =IF(B20="","",B20&"-EV-"&TEXT(17,"000"))
A21: 18 | C21: =IF(B21="","",B21&"-EV-"&TEXT(18,"000"))
A22: 19 | C22: =IF(B22="","",B22&"-EV-"&TEXT(19,"000"))
A23: 20 | C23: =IF(B23="","",B23&"-EV-"&TEXT(20,"000"))
A24: 21 | C24: =IF(B24="","",B24&"-EV-"&TEXT(21,"000"))
A25: 22 | C25: =IF(B25="","",B25&"-EV-"&TEXT(22,"000"))
A26: 23 | C26: =IF(B26="","",B26&"-EV-"&TEXT(23,"000"))
A27: 24 | C27: =IF(B27="","",B27&"-EV-"&TEXT(24,"000"))
A28: 25 | C28: =IF(B28="","",B28&"-EV-"&TEXT(25,"000"))
A29: 26 | C29: =IF(B29="","",B29&"-EV-"&TEXT(26,"000"))
A30: 27 | C30: =IF(B30="","",B30&"-EV-"&TEXT(27,"000"))
A31: 28 | C31: =IF(B31="","",B31&"-EV-"&TEXT(28,"000"))
A32: 29 | C32: =IF(B32="","",B32&"-EV-"&TEXT(29,"000"))
A33: 30 | C33: =IF(B33="","",B33&"-EV-"&TEXT(30,"000"))
A34: 31 | C34: =IF(B34="","",B34&"-EV-"&TEXT(31,"000"))
A35: 32 | C35: =IF(B35="","",B35&"-EV-"&TEXT(32,"000"))
A36: 33 | C36: =IF(B36="","",B36&"-EV-"&TEXT(33,"000"))
A37: 34 | C37: =IF(B37="","",B37&"-EV-"&TEXT(34,"000"))
A38: 35 | C38: =IF(B38="","",B38&"-EV-"&TEXT(35,"000"))
A39: 36 | C39: =IF(B39="","",B39&"-EV-"&TEXT(36,"000"))
A40: 37 | C40: =IF(B40="","",B40&"-EV-"&TEXT(37,"000"))
...

Sheet 📊 Dashboard
A1: SolidPro — Content & Digital Dashboard (File 2 of 2)
A2: Auto-calculated from all sheets | Press Ctrl+Alt+F9 to force refresh
A4: Assets by Tracker Sheet | D4: Count
A5: 🌐 Landing Pages | D5: =COUNTIFS('🌐 Landing Pages'!$B$4:$B$103,"<>",'🌐 Landing Pages'!$E$4:$E$103,"<>")
A6: ✍ Content Writing | D6: =COUNTIFS('✍ Content Writing'!$B$4:$B$103,"<>",'✍ Content Writing'!$E$4:$E$103,"<>")
A7: 🎁 Lead Magnets | D7: =COUNTIFS('🎁 Lead Magnets'!$B$4:$B$103,"<>",'🎁 Lead Magnets'!$E$4:$E$103,"<>")
A8: 📧 Email Sequences | D8: =COUNTIFS('📧 Email Sequences'!$B$4:$B$103,"<>",'📧 Email Sequences'!$E$4:$E$103,"<>")
A9: 🔍 SEO | D9: =COUNTIFS('🔍 SEO'!$B$4:$B$103,"<>",'🔍 SEO'!$E$4:$E$103,"<>")
A10: 🎤 Webinars & Events | D10: =COUNTIFS('🎤 Webinars & Events'!$B$4:$B$103,"<>",'🎤 Webinars & Events'!$E$4:$E$103,"<>")
A12: Landing Pages by Status | D12: Count
A13: 📋 Briefed | D13: =COUNTIF('🌐 Landing Pages'!V4:V103,"*Briefed*")
A14: ✍ In Progress | D14: =COUNTIF('🌐 Landing Pages'!V4:V103,"*Progress*")
A15: ✅ Approved | D15: =COUNTIF('🌐 Landing Pages'!V4:V103,"*Approved*")
A16: 🚀 Live | D16: =COUNTIF('🌐 Landing Pages'!V4:V103,"*Live*")
A17: ⏸ On Hold | D17: =COUNTIF('🌐 Landing Pages'!V4:V103,"*On Hold*")
A18: ❌ Cancelled | D18: =COUNTIF('🌐 Landing Pages'!V4:V103,"*Cancelled*")
A20: Lead Magnets by Type | D20: Count
A21: Downloadable PDF | D21: =COUNTIF('🎁 Lead Magnets'!F4:F103,"*PDF*")
A22: Assessment / Quiz | D22: =COUNTIF('🎁 Lead Magnets'!F4:F103,"*Assessment*")
A23: Checklist | D23: =COUNTIF('🎁 Lead Magnets'!F4:F103,"*Checklist*")
A24: Template | D24: =COUNTIF('🎁 Lead Magnets'!F4:F103,"*Template*")
A25: Calculator | D25: =COUNTIF('🎁 Lead Magnets'!F4:F103,"*Calculator*")
A26: eBook | D26: =COUNTIF('🎁 Lead Magnets'!F4:F103,"*eBook*")
A27: Other | D27: =COUNTIF('🎁 Lead Magnets'!F4:F103,"*Other*")
A29: SEO Tasks by Type | D29: Count
A30: Keyword Research | D30: =COUNTIF('🔍 SEO'!F4:F103,"*Keyword*")
A31: On-Page Optimisation | D31: =COUNTIF('🔍 SEO'!F4:F103,"*On-Page*")
A32: Technical SEO | D32: =COUNTIF('🔍 SEO'!F4:F103,"*Technical*")
A33: Content Optimisation | D33: =COUNTIF('🔍 SEO'!F4:F103,"*Content Opt*")
A34: Link Building | D34: =COUNTIF('🔍 SEO'!F4:F103,"*Link*")
A35: Site Audit | D35: =COUNTIF('🔍 SEO'!F4:F103,"*Audit*")
A37: Events by Type | D37: Count
A38: Webinar | D38: =COUNTIF('🎤 Webinars & Events'!F4:F103,"*Webinar*")
A39: Workshop | D39: =COUNTIF('🎤 Webinars & Events'!F4:F103,"*Workshop*")
A40: In-Person Event | D40: =COUNTIF('🎤 Webinars & Events'!F4:F103,"*In-Person*")
A41: Virtual Event | D41: =COUNTIF('🎤 Webinars & Events'!F4:F103,"*Virtual*")
A42: Roundtable | D42: =COUNTIF('🎤 Webinars & Events'!F4:F103,"*Roundtable*")
